{
  "version": 8,
  "blockIdVersion": 3,
  "anchorX": 0,
  "anchorY": 0,
  "anchorZ": 0,
  "blocks": [
    {
      "x": -4,
      "y": 0,
      "z": -2,
      "name": "Empty"
    },
    {
      "x": -4,
      "y": 1,
      "z": -2,
      "name": "Empty"
    },
    {
      "x": -4,
      "y": 2,
      "z": -2,
      "name": "Empty"
    },
    {
      "x": -4,
      "y": 3,
      "z": -2,
      "name": "Wood_Oak_Trunk",
      "support": 15,
      "rotation": 4
    },
    {
      "x": -4,
      "y": 4,
      "z": -2,
      "name": "Wood_Oak_Trunk",
      "support": 15
    },
    {
      "x": -4,
      "y": 5,
      "z": -2,
      "name": "Wood_Oak_Trunk",
      "support": 15
    },
    {
      "x": -4,
      "y": 6,
      "z": -2,
      "name": "Wood_Oak_Trunk",
      "support": 15
    },
    {
      "x": -4,
      "y": 7,
      "z": -2,
      "name": "HyDomum_Shingle__Soil_Clay_Smooth_Orange__Wood_Hardwood_Planks",
      "rotation": 3
    },
    {
      "x": -4,
      "y": 8,
      "z": -2,
      "name": "Empty"
    },
    {
      "x": -4,
      "y": 9,
      "z": -2,
      "name": "Empty"
    },
    {
      "x": -4,
      "y": 10,
      "z": -2,
      "name": "Empty"
    },
    {
      "x": -4,
      "y": 11,
      "z": -2,
      "name": "Empty"
    },
    {
      "x": -4,
      "y": 12,
      "z": -2,
      "name": "Empty"
    },
    {
      "x": -4,
      "y": 13,
      "z": -2,
      "name": "Empty"
    },
    {
      "x": -4,
      "y": -6,
      "z": -1,
      "name": "Rock_Stone_Brick"
    },
    {
      "x": -4,
      "y": -5,
      "z": -1,
      "name": "Rock_Stone_Brick"
    },
    {
      "x": -4,
      "y": -4,
      "z": -1,
      "name": "Rock_Stone_Brick"
    },
    {
      "x": -4,
      "y": -3,
      "z": -1,
      "name": "Rock_Stone_Brick"
    },
    {
      "x": -4,
      "y": -2,
      "z": -1,
      "name": "Rock_Stone_Brick"
    },
    {
      "x": -4,
      "y": -1,
      "z": -1,
      "name": "Rock_Stone_Brick"
    },
    {
      "x": -4,
      "y": 0,
      "z": -1,
      "name": "Rock_Stone_Brick"
    },
    {
      "x": -4,
      "y": 1,
      "z": -1,
      "name": "Rock_Stone_Brick"
    },
    {
      "x": -4,
      "y": 2,
      "z": -1,
      "name": "Rock_Stone_Brick"
    },
    {
      "x": -4,
      "y": 3,
      "z": -1,
      "name": "Wood_Oak_Trunk",
      "support": 15,
      "rotation": 4
    },
    {
      "x": -4,
      "y": 4,
      "z": -1,
      "name": "HyDomum_TimberFrame_Plain__Wood_Hardwood_Planks__Wood_Hardwood_Planks"
    },
    {
      "x": -4,
      "y": 5,
      "z": -1,
      "name": "HyDomum_TimberFrame_OneCrossedLr__Wood_Hardwood_Planks__Soil_Clay_Smooth_White"
    },
    {
      "x": -4,
      "y": 6,
      "z": -1,
      "name": "HyDomum_TimberFrame_OneCrossedLr__Wood_Hardwood_Planks__Soil_Clay_Smooth_White"
    },
    {
      "x": -4,
      "y": 7,
      "z": -1,
      "name": "HyDomum_Shingle__Soil_Clay_Brick__Wood_Hardwood_Planks",
      "rotation": 3
    },
    {
      "x": -4,
      "y": 8,
      "z": -1,
      "name": "Empty"
    },
    {
      "x": -4,
      "y": 9,
      "z": -1,
      "name": "Empty"
    },
    {
      "x": -4,
      "y": 10,
      "z": -1,
      "name": "Empty"
    },
    {
      "x": -4,
      "y": 11,
      "z": -1,
      "name": "Empty"
    },
    {
      "x": -4,
      "y": 12,
      "z": -1,
      "name": "Empty"
    },
    {
      "x": -4,
      "y": 13,
      "z": -1,
      "name": "Empty"
    },
    {
      "x": -4,
      "y": -6,
      "z": 0,
      "name": "Rock_Stone_Brick"
    },
    {
      "x": -4,
      "y": -5,
      "z": 0,
      "name": "Rock_Stone_Cobble"
    },
    {
      "x": -4,
      "y": -4,
      "z": 0,
      "name": "Rock_Stone_Cobble"
    },
    {
      "x": -4,
      "y": -3,
      "z": 0,
      "name": "Rock_Stone_Cobble"
    },
    {
      "x": -4,
      "y": -2,
      "z": 0,
      "name": "Rock_Stone_Cobble"
    },
    {
      "x": -4,
      "y": -1,
      "z": 0,
      "name": "Rock_Stone_Cobble"
    },
    {
      "x": -4,
      "y": 0,
      "z": 0,
      "name": "Rock_Stone_Cobble"
    },
    {
      "x": -4,
      "y": 1,
      "z": 0,
      "name": "Rock_Stone_Cobble"
    },
    {
      "x": -4,
      "y": 2,
      "z": 0,
      "name": "Rock_Stone_Cobble"
    },
    {
      "x": -4,
      "y": 3,
      "z": 0,
      "name": "Wood_Oak_Trunk",
      "support": 15,
      "rotation": 4
    },
    {
      "x": -4,
      "y": 4,
      "z": 0,
      "name": "HyDomum_TimberFrame_Plain__Wood_Hardwood_Planks__Wood_Hardwood_Planks"
    },
    {
      "x": -4,
      "y": 5,
      "z": 0,
      "name": "HyDomum_TimberFrame_Plain__Wood_Hardwood_Planks__Soil_Clay_Smooth_White"
    },
    {
      "x": -4,
      "y": 6,
      "z": 0,
      "name": "HyDomum_TimberFrame_Plain__Wood_Hardwood_Planks__Soil_Clay_Smooth_White"
    },
    {
      "x": -4,
      "y": 7,
      "z": 0,
      "name": "HyDomum_Shingle__Soil_Clay_Brick__Wood_Hardwood_Planks",
      "rotation": 3
    },
    {
      "x": -4,
      "y": 8,
      "z": 0,
      "name": "Empty"
    },
    {
      "x": -4,
      "y": 9,
      "z": 0,
      "name": "Empty"
    },
    {
      "x": -4,
      "y": 10,
      "z": 0,
      "name": "Empty"
    },
    {
      "x": -4,
      "y": 11,
      "z": 0,
      "name": "Empty"
    },
    {
      "x": -4,
      "y": 12,
      "z": 0,
      "name": "Empty"
    },
    {
      "x": -4,
      "y": 13,
      "z": 0,
      "name": "Empty"
    },
    {
      "x": -4,
      "y": -6,
      "z": 1,
      "name": "Rock_Stone_Brick"
    },
    {
      "x": -4,
      "y": -5,
      "z": 1,
      "name": "Rock_Stone_Cobble"
    },
    {
      "x": -4,
      "y": -4,
      "z": 1,
      "name": "Rock_Stone_Cobble"
    },
    {
      "x": -4,
      "y": -3,
      "z": 1,
      "name": "Rock_Stone_Cobble"
    },
    {
      "x": -4,
      "y": -2,
      "z": 1,
      "name": "Rock_Stone_Cobble"
    },
    {
      "x": -4,
      "y": -1,
      "z": 1,
      "name": "Rock_Stone_Cobble"
    },
    {
      "x": -4,
      "y": 0,
      "z": 1,
      "name": "Rock_Stone_Cobble"
    },
    {
      "x": -4,
      "y": 1,
      "z": 1,
      "name": "Rock_Stone_Cobble"
    },
    {
      "x": -4,
      "y": 2,
      "z": 1,
      "name": "Rock_Stone_Cobble"
    },
    {
      "x": -4,
      "y": 3,
      "z": 1,
      "name": "Wood_Oak_Trunk",
      "support": 15,
      "rotation": 4
    },
    {
      "x": -4,
      "y": 4,
      "z": 1,
      "name": "HyDomum_TimberFrame_Plain__Wood_Hardwood_Planks__Wood_Hardwood_Planks"
    },
    {
      "x": -4,
      "y": 5,
      "z": 1,
      "name": "HyDomum_TimberFrame_OneCrossedRl__Wood_Hardwood_Planks__Soil_Clay_Smooth_White"
    },
    {
      "x": -4,
      "y": 6,
      "z": 1,
      "name": "HyDomum_TimberFrame_OneCrossedRl__Wood_Hardwood_Planks__Soil_Clay_Smooth_White"
    },
    {
      "x": -4,
      "y": 7,
      "z": 1,
      "name": "HyDomum_Shingle__Soil_Clay_Brick__Wood_Hardwood_Planks",
      "rotation": 3
    },
    {
      "x": -4,
      "y": 8,
      "z": 1,
      "name": "Empty"
    },
    {
      "x": -4,
      "y": 9,
      "z": 1,
      "name": "Empty"
    },
    {
      "x": -4,
      "y": 10,
      "z": 1,
      "name": "Empty"
    },
    {
      "x": -4,
      "y": 11,
      "z": 1,
      "name": "Empty"
    },
    {
      "x": -4,
      "y": 12,
      "z": 1,
      "name": "Empty"
    },
    {
      "x": -4,
      "y": 13,
      "z": 1,
      "name": "Empty"
    },
    {
      "x": -4,
      "y": -6,
      "z": 2,
      "name": "Rock_Stone_Brick"
    },
    {
      "x": -4,
      "y": -5,
      "z": 2,
      "name": "Rock_Stone_Cobble"
    },
    {
      "x": -4,
      "y": -4,
      "z": 2,
      "name": "Rock_Stone_Cobble"
    },
    {
      "x": -4,
      "y": -3,
      "z": 2,
      "name": "Rock_Stone_Cobble"
    },
    {
      "x": -4,
      "y": -2,
      "z": 2,
      "name": "Rock_Stone_Cobble"
    },
    {
      "x": -4,
      "y": -1,
      "z": 2,
      "name": "Rock_Stone_Cobble"
    },
    {
      "x": -4,
      "y": 0,
      "z": 2,
      "name": "Rock_Stone_Cobble"
    },
    {
      "x": -4,
      "y": 1,
      "z": 2,
      "name": "Rock_Stone_Cobble"
    },
    {
      "x": -4,
      "y": 2,
      "z": 2,
      "name": "Rock_Stone_Cobble"
    },
    {
      "x": -4,
      "y": 3,
      "z": 2,
      "name": "Wood_Oak_Trunk",
      "support": 15,
      "rotation": 4
    },
    {
      "x": -4,
      "y": 4,
      "z": 2,
      "name": "Wood_Oak_Trunk",
      "support": 15
    },
    {
      "x": -4,
      "y": 5,
      "z": 2,
      "name": "Wood_Oak_Trunk",
      "support": 15
    },
    {
      "x": -4,
      "y": 6,
      "z": 2,
      "name": "Wood_Oak_Trunk",
      "support": 15
    },
    {
      "x": -4,
      "y": 7,
      "z": 2,
      "name": "HyDomum_Shingle__Soil_Clay_Smooth_Orange__Wood_Hardwood_Planks",
      "rotation": 3
    },
    {
      "x": -4,
      "y": 8,
      "z": 2,
      "name": "Empty"
    },
    {
      "x": -4,
      "y": 9,
      "z": 2,
      "name": "Empty"
    },
    {
      "x": -4,
      "y": 10,
      "z": 2,
      "name": "Empty"
    },
    {
      "x": -4,
      "y": 11,
      "z": 2,
      "name": "Empty"
    },
    {
      "x": -4,
      "y": 12,
      "z": 2,
      "name": "Empty"
    },
    {
      "x": -4,
      "y": 13,
      "z": 2,
      "name": "Empty"
    },
    {
      "x": -4,
      "y": -6,
      "z": 3,
      "name": "Rock_Stone_Brick"
    },
    {
      "x": -4,
      "y": -5,
      "z": 3,
      "name": "Rock_Stone_Brick"
    },
    {
      "x": -4,
      "y": -4,
      "z": 3,
      "name": "Rock_Stone_Brick"
    },
    {
      "x": -4,
      "y": -3,
      "z": 3,
      "name": "Rock_Stone_Brick"
    },
    {
      "x": -4,
      "y": -2,
      "z": 3,
      "name": "Rock_Stone_Brick"
    },
    {
      "x": -4,
      "y": -1,
      "z": 3,
      "name": "Rock_Stone_Brick"
    },
    {
      "x": -4,
      "y": 0,
      "z": 3,
      "name": "Rock_Stone_Brick"
    },
    {
      "x": -4,
      "y": 1,
      "z": 3,
      "name": "Rock_Stone_Brick"
    },
    {
      "x": -4,
      "y": 2,
      "z": 3,
      "name": "Rock_Stone_Brick"
    },
    {
      "x": -4,
      "y": 3,
      "z": 3,
      "name": "Wood_Oak_Trunk",
      "support": 15,
      "rotation": 4
    },
    {
      "x": -4,
      "y": 4,
      "z": 3,
      "name": "HyDomum_TimberFrame_Plain__Wood_Hardwood_Planks__Wood_Hardwood_Planks"
    },
    {
      "x": -4,
      "y": 5,
      "z": 3,
      "name": "HyDomum_TimberFrame_OneCrossedLr__Wood_Hardwood_Planks__Soil_Clay_Smooth_White"
    },
    {
      "x": -4,
      "y": 6,
      "z": 3,
      "name": "HyDomum_TimberFrame_OneCrossedLr__Wood_Hardwood_Planks__Soil_Clay_Smooth_White"
    },
    {
      "x": -4,
      "y": 7,
      "z": 3,
      "name": "HyDomum_Shingle__Soil_Clay_Brick__Wood_Hardwood_Planks",
      "rotation": 3
    },
    {
      "x": -4,
      "y": 8,
      "z": 3,
      "name": "Empty"
    },
    {
      "x": -4,
      "y": 9,
      "z": 3,
      "name": "Empty"
    },
    {
      "x": -4,
      "y": 10,
      "z": 3,
      "name": "Empty"
    },
    {
      "x": -4,
      "y": 11,
      "z": 3,
      "name": "Empty"
    },
    {
      "x": -4,
      "y": 12,
      "z": 3,
      "name": "Empty"
    },
    {
      "x": -4,
      "y": 13,
      "z": 3,
      "name": "Empty"
    },
    {
      "x": -4,
      "y": 0,
      "z": 4,
      "name": "Empty"
    },
    {
      "x": -4,
      "y": 1,
      "z": 4,
      "name": "Empty"
    },
    {
      "x": -4,
      "y": 2,
      "z": 4,
      "name": "Empty"
    },
    {
      "x": -4,
      "y": 3,
      "z": 4,
      "name": "Wood_Oak_Trunk",
      "support": 15,
      "rotation": 4
    },
    {
      "x": -4,
      "y": 4,
      "z": 4,
      "name": "HyDomum_TimberFrame_Plain__Wood_Hardwood_Planks__Wood_Hardwood_Planks"
    },
    {
      "x": -4,
      "y": 5,
      "z": 4,
      "name": "HyDomum_TimberFrame_Plain__Wood_Hardwood_Planks__Soil_Clay_Smooth_White"
    },
    {
      "x": -4,
      "y": 6,
      "z": 4,
      "name": "HyDomum_TimberFrame_Plain__Wood_Hardwood_Planks__Soil_Clay_Smooth_White"
    },
    {
      "x": -4,
      "y": 7,
      "z": 4,
      "name": "HyDomum_Shingle__Soil_Clay_Brick__Wood_Hardwood_Planks",
      "rotation": 3
    },
    {
      "x": -4,
      "y": 8,
      "z": 4,
      "name": "Empty"
    },
    {
      "x": -4,
      "y": 9,
      "z": 4,
      "name": "Empty"
    },
    {
      "x": -4,
      "y": 10,
      "z": 4,
      "name": "Empty"
    },
    {
      "x": -4,
      "y": 11,
      "z": 4,
      "name": "Empty"
    },
    {
      "x": -4,
      "y": 12,
      "z": 4,
      "name": "Empty"
    },
    {
      "x": -4,
      "y": 13,
      "z": 4,
      "name": "Empty"
    },
    {
      "x": -4,
      "y": 0,
      "z": 5,
      "name": "Empty"
    },
    {
      "x": -4,
      "y": 1,
      "z": 5,
      "name": "Empty"
    },
    {
      "x": -4,
      "y": 2,
      "z": 5,
      "name": "Empty"
    },
    {
      "x": -4,
      "y": 3,
      "z": 5,
      "name": "Wood_Oak_Trunk",
      "support": 15,
      "rotation": 4
    },
    {
      "x": -4,
      "y": 4,
      "z": 5,
      "name": "HyDomum_TimberFrame_Plain__Wood_Hardwood_Planks__Wood_Hardwood_Planks"
    },
    {
      "x": -4,
      "y": 5,
      "z": 5,
      "name": "HyDomum_TimberFrame_OneCrossedRl__Wood_Hardwood_Planks__Soil_Clay_Smooth_White"
    },
    {
      "x": -4,
      "y": 6,
      "z": 5,
      "name": "HyDomum_TimberFrame_OneCrossedRl__Wood_Hardwood_Planks__Soil_Clay_Smooth_White"
    },
    {
      "x": -4,
      "y": 7,
      "z": 5,
      "name": "HyDomum_Shingle__Soil_Clay_Brick__Wood_Hardwood_Planks",
      "rotation": 3
    },
    {
      "x": -4,
      "y": 8,
      "z": 5,
      "name": "Empty"
    },
    {
      "x": -4,
      "y": 9,
      "z": 5,
      "name": "Empty"
    },
    {
      "x": -4,
      "y": 10,
      "z": 5,
      "name": "Empty"
    },
    {
      "x": -4,
      "y": 11,
      "z": 5,
      "name": "Empty"
    },
    {
      "x": -4,
      "y": 12,
      "z": 5,
      "name": "Empty"
    },
    {
      "x": -4,
      "y": 13,
      "z": 5,
      "name": "Empty"
    },
    {
      "x": -4,
      "y": 0,
      "z": 6,
      "name": "Empty"
    },
    {
      "x": -4,
      "y": 1,
      "z": 6,
      "name": "Empty"
    },
    {
      "x": -4,
      "y": 2,
      "z": 6,
      "name": "Empty"
    },
    {
      "x": -4,
      "y": 3,
      "z": 6,
      "name": "Wood_Oak_Trunk",
      "support": 15,
      "rotation": 4
    },
    {
      "x": -4,
      "y": 4,
      "z": 6,
      "name": "Wood_Oak_Trunk",
      "support": 15
    },
    {
      "x": -4,
      "y": 5,
      "z": 6,
      "name": "Wood_Oak_Trunk",
      "support": 15
    },
    {
      "x": -4,
      "y": 6,
      "z": 6,
      "name": "Wood_Oak_Trunk",
      "support": 15
    },
    {
      "x": -4,
      "y": 7,
      "z": 6,
      "name": "HyDomum_Shingle__Soil_Clay_Smooth_Orange__Wood_Hardwood_Planks",
      "rotation": 3
    },
    {
      "x": -4,
      "y": 8,
      "z": 6,
      "name": "Empty"
    },
    {
      "x": -4,
      "y": 9,
      "z": 6,
      "name": "Empty"
    },
    {
      "x": -4,
      "y": 10,
      "z": 6,
      "name": "Empty"
    },
    {
      "x": -4,
      "y": 11,
      "z": 6,
      "name": "Empty"
    },
    {
      "x": -4,
      "y": 12,
      "z": 6,
      "name": "Empty"
    },
    {
      "x": -4,
      "y": 13,
      "z": 6,
      "name": "Empty"
    },
    {
      "x": -4,
      "y": 0,
      "z": 7,
      "name": "Empty"
    },
    {
      "x": -4,
      "y": 1,
      "z": 7,
      "name": "Empty"
    },
    {
      "x": -4,
      "y": 2,
      "z": 7,
      "name": "Empty"
    },
    {
      "x": -4,
      "y": 3,
      "z": 7,
      "name": "Wood_Oak_Trunk",
      "support": 15,
      "rotation": 4
    },
    {
      "x": -4,
      "y": 4,
      "z": 7,
      "name": "HyDomum_TimberFrame_Plain__Wood_Hardwood_Planks__Wood_Hardwood_Planks"
    },
    {
      "x": -4,
      "y": 5,
      "z": 7,
      "name": "HyDomum_TimberFrame_OneCrossedLr__Wood_Hardwood_Planks__Soil_Clay_Smooth_White"
    },
    {
      "x": -4,
      "y": 6,
      "z": 7,
      "name": "HyDomum_TimberFrame_OneCrossedLr__Wood_Hardwood_Planks__Soil_Clay_Smooth_White"
    },
    {
      "x": -4,
      "y": 7,
      "z": 7,
      "name": "HyDomum_Shingle__Soil_Clay_Brick__Wood_Hardwood_Planks",
      "rotation": 3
    },
    {
      "x": -4,
      "y": 8,
      "z": 7,
      "name": "Empty"
    },
    {
      "x": -4,
      "y": 9,
      "z": 7,
      "name": "Empty"
    },
    {
      "x": -4,
      "y": 10,
      "z": 7,
      "name": "Empty"
    },
    {
      "x": -4,
      "y": 11,
      "z": 7,
      "name": "Empty"
    },
    {
      "x": -4,
      "y": 12,
      "z": 7,
      "name": "Empty"
    },
    {
      "x": -4,
      "y": 13,
      "z": 7,
      "name": "Empty"
    },
    {
      "x": -4,
      "y": 0,
      "z": 8,
      "name": "Empty"
    },
    {
      "x": -4,
      "y": 1,
      "z": 8,
      "name": "Empty"
    },
    {
      "x": -4,
      "y": 2,
      "z": 8,
      "name": "Empty"
    },
    {
      "x": -4,
      "y": 3,
      "z": 8,
      "name": "Wood_Oak_Trunk",
      "support": 15,
      "rotation": 4
    },
    {
      "x": -4,
      "y": 4,
      "z": 8,
      "name": "HyDomum_TimberFrame_Plain__Wood_Hardwood_Planks__Wood_Hardwood_Planks"
    },
    {
      "x": -4,
      "y": 5,
      "z": 8,
      "name": "HyDomum_TimberFrame_OneCrossedRl__Wood_Hardwood_Planks__Soil_Clay_Smooth_White"
    },
    {
      "x": -4,
      "y": 6,
      "z": 8,
      "name": "HyDomum_TimberFrame_OneCrossedRl__Wood_Hardwood_Planks__Soil_Clay_Smooth_White"
    },
    {
      "x": -4,
      "y": 7,
      "z": 8,
      "name": "HyDomum_Shingle__Soil_Clay_Brick__Wood_Hardwood_Planks",
      "rotation": 3
    },
    {
      "x": -4,
      "y": 8,
      "z": 8,
      "name": "Empty"
    },
    {
      "x": -4,
      "y": 9,
      "z": 8,
      "name": "Empty"
    },
    {
      "x": -4,
      "y": 10,
      "z": 8,
      "name": "Empty"
    },
    {
      "x": -4,
      "y": 11,
      "z": 8,
      "name": "Empty"
    },
    {
      "x": -4,
      "y": 12,
      "z": 8,
      "name": "Empty"
    },
    {
      "x": -4,
      "y": 13,
      "z": 8,
      "name": "Empty"
    },
    {
      "x": -4,
      "y": 0,
      "z": 9,
      "name": "Empty"
    },
    {
      "x": -4,
      "y": 1,
      "z": 9,
      "name": "Empty"
    },
    {
      "x": -4,
      "y": 2,
      "z": 9,
      "name": "Empty"
    },
    {
      "x": -4,
      "y": 3,
      "z": 9,
      "name": "Wood_Oak_Trunk",
      "support": 15,
      "rotation": 4
    },
    {
      "x": -4,
      "y": 4,
      "z": 9,
      "name": "Wood_Oak_Trunk",
      "support": 15
    },
    {
      "x": -4,
      "y": 5,
      "z": 9,
      "name": "Wood_Oak_Trunk",
      "support": 15
    },
    {
      "x": -4,
      "y": 6,
      "z": 9,
      "name": "Wood_Oak_Trunk",
      "support": 15
    },
    {
      "x": -4,
      "y": 7,
      "z": 9,
      "name": "HyDomum_Shingle__Soil_Clay_Smooth_Orange__Wood_Hardwood_Planks",
      "rotation": 3
    },
    {
      "x": -4,
      "y": 8,
      "z": 9,
      "name": "Empty"
    },
    {
      "x": -4,
      "y": 9,
      "z": 9,
      "name": "Empty"
    },
    {
      "x": -4,
      "y": 10,
      "z": 9,
      "name": "Empty"
    },
    {
      "x": -4,
      "y": 11,
      "z": 9,
      "name": "Empty"
    },
    {
      "x": -4,
      "y": 12,
      "z": 9,
      "name": "Empty"
    },
    {
      "x": -4,
      "y": 13,
      "z": 9,
      "name": "Empty"
    },
    {
      "x": -4,
      "y": 0,
      "z": 10,
      "name": "Empty"
    },
    {
      "x": -4,
      "y": 1,
      "z": 10,
      "name": "Empty"
    },
    {
      "x": -4,
      "y": 2,
      "z": 10,
      "name": "Empty"
    },
    {
      "x": -4,
      "y": 3,
      "z": 10,
      "name": "Empty"
    },
    {
      "x": -4,
      "y": 4,
      "z": 10,
      "name": "Empty"
    },
    {
      "x": -4,
      "y": 5,
      "z": 10,
      "name": "Empty"
    },
    {
      "x": -4,
      "y": 6,
      "z": 10,
      "name": "Wood_Oak_Trunk",
      "support": 15,
      "rotation": 4
    },
    {
      "x": -4,
      "y": 7,
      "z": 10,
      "name": "HyDomum_Shingle__Soil_Clay_Brick__Wood_Hardwood_Planks",
      "rotation": 3
    },
    {
      "x": -4,
      "y": 8,
      "z": 10,
      "name": "Empty"
    },
    {
      "x": -4,
      "y": 9,
      "z": 10,
      "name": "Empty"
    },
    {
      "x": -4,
      "y": 10,
      "z": 10,
      "name": "Empty"
    },
    {
      "x": -4,
      "y": 11,
      "z": 10,
      "name": "Empty"
    },
    {
      "x": -4,
      "y": 12,
      "z": 10,
      "name": "Empty"
    },
    {
      "x": -4,
      "y": 13,
      "z": 10,
      "name": "Empty"
    },
    {
      "x": -4,
      "y": 0,
      "z": 11,
      "name": "Empty"
    },
    {
      "x": -4,
      "y": 1,
      "z": 11,
      "name": "Empty"
    },
    {
      "x": -4,
      "y": 2,
      "z": 11,
      "name": "Empty"
    },
    {
      "x": -4,
      "y": 3,
      "z": 11,
      "name": "Empty"
    },
    {
      "x": -4,
      "y": 4,
      "z": 11,
      "name": "Empty"
    },
    {
      "x": -4,
      "y": 5,
      "z": 11,
      "name": "Empty"
    },
    {
      "x": -4,
      "y": 6,
      "z": 11,
      "name": "Empty"
    },
    {
      "x": -4,
      "y": 7,
      "z": 11,
      "name": "Empty"
    },
    {
      "x": -4,
      "y": 8,
      "z": 11,
      "name": "Empty"
    },
    {
      "x": -4,
      "y": 9,
      "z": 11,
      "name": "Empty"
    },
    {
      "x": -4,
      "y": 10,
      "z": 11,
      "name": "Empty"
    },
    {
      "x": -4,
      "y": 11,
      "z": 11,
      "name": "Empty"
    },
    {
      "x": -4,
      "y": 12,
      "z": 11,
      "name": "Empty"
    },
    {
      "x": -4,
      "y": 13,
      "z": 11,
      "name": "Empty"
    },
    {
      "x": -3,
      "y": 0,
      "z": -2,
      "name": "Empty"
    },
    {
      "x": -3,
      "y": 1,
      "z": -2,
      "name": "Empty"
    },
    {
      "x": -3,
      "y": 2,
      "z": -2,
      "name": "Empty"
    },
    {
      "x": -3,
      "y": 3,
      "z": -2,
      "name": "Wood_Oak_Trunk",
      "support": 15,
      "rotation": 5
    },
    {
      "x": -3,
      "y": 4,
      "z": -2,
      "name": "HyDomum_TimberFrame_Plain__Wood_Hardwood_Planks__Wood_Hardwood_Planks"
    },
    {
      "x": -3,
      "y": 5,
      "z": -2,
      "name": "HyDomum_TimberFrame_OneCrossedRl__Wood_Hardwood_Planks__Soil_Clay_Smooth_White"
    },
    {
      "x": -3,
      "y": 6,
      "z": -2,
      "name": "HyDomum_TimberFrame_OneCrossedRl__Wood_Hardwood_Planks__Soil_Clay_Smooth_White"
    },
    {
      "x": -3,
      "y": 7,
      "z": -2,
      "name": "Wood_Oak_Trunk",
      "support": 15,
      "rotation": 5
    },
    {
      "x": -3,
      "y": 8,
      "z": -2,
      "name": "HyDomum_Shingle__Soil_Clay_Brick__Wood_Hardwood_Planks",
      "rotation": 3
    },
    {
      "x": -3,
      "y": 9,
      "z": -2,
      "name": "Empty"
    },
    {
      "x": -3,
      "y": 10,
      "z": -2,
      "name": "Empty"
    },
    {
      "x": -3,
      "y": 11,
      "z": -2,
      "name": "Empty"
    },
    {
      "x": -3,
      "y": 12,
      "z": -2,
      "name": "Empty"
    },
    {
      "x": -3,
      "y": 13,
      "z": -2,
      "name": "Empty"
    },
    {
      "x": -3,
      "y": -6,
      "z": -1,
      "name": "Rock_Stone_Brick"
    },
    {
      "x": -3,
      "y": -5,
      "z": -1,
      "name": "Rock_Stone_Cobble"
    },
    {
      "x": -3,
      "y": -4,
      "z": -1,
      "name": "Rock_Stone_Cobble"
    },
    {
      "x": -3,
      "y": -3,
      "z": -1,
      "name": "Rock_Stone_Cobble"
    },
    {
      "x": -3,
      "y": -2,
      "z": -1,
      "name": "Rock_Stone_Cobble"
    },
    {
      "x": -3,
      "y": -1,
      "z": -1,
      "name": "Rock_Stone_Cobble"
    },
    {
      "x": -3,
      "y": 0,
      "z": -1,
      "name": "Rock_Stone_Cobble"
    },
    {
      "x": -3,
      "y": 1,
      "z": -1,
      "name": "Rock_Stone_Cobble"
    },
    {
      "x": -3,
      "y": 2,
      "z": -1,
      "name": "Rock_Stone_Cobble"
    },
    {
      "x": -3,
      "y": 3,
      "z": -1,
      "name": "Wood_Oak_Trunk",
      "support": 15,
      "rotation": 5
    },
    {
      "x": -3,
      "y": 4,
      "z": -1,
      "name": "Empty"
    },
    {
      "x": -3,
      "y": 5,
      "z": -1,
      "name": "Empty"
    },
    {
      "x": -3,
      "y": 6,
      "z": -1,
      "name": "Empty"
    },
    {
      "x": -3,
      "y": 7,
      "z": -1,
      "name": "Wood_Hardwood_Stairs",
      "rotation": 11
    },
    {
      "x": -3,
      "y": 8,
      "z": -1,
      "name": "HyDomum_Shingle__Soil_Clay_Smooth_Orange__Wood_Hardwood_Planks",
      "rotation": 3
    },
    {
      "x": -3,
      "y": 9,
      "z": -1,
      "name": "Empty"
    },
    {
      "x": -3,
      "y": 10,
      "z": -1,
      "name": "Empty"
    },
    {
      "x": -3,
      "y": 11,
      "z": -1,
      "name": "Empty"
    },
    {
      "x": -3,
      "y": 12,
      "z": -1,
      "name": "Empty"
    },
    {
      "x": -3,
      "y": 13,
      "z": -1,
      "name": "Empty"
    },
    {
      "x": -3,
      "y": -6,
      "z": 0,
      "name": "Rock_Stone_Cobble"
    },
    {
      "x": -3,
      "y": -5,
      "z": 0,
      "name": "Rock_Stone_Brick"
    },
    {
      "x": -3,
      "y": -4,
      "z": 0,
      "name": "Rock_Stone_Cobble"
    },
    {
      "x": -3,
      "y": -3,
      "z": 0,
      "name": "Rock_Stone_Cobble"
    },
    {
      "x": -3,
      "y": -2,
      "z": 0,
      "name": "Rock_Stone_Brick"
    },
    {
      "x": -3,
      "y": -1,
      "z": 0,
      "name": "Rock_Stone_Cobble_Stairs"
    },
    {
      "x": -3,
      "y": 0,
      "z": 0,
      "name": "Empty"
    },
    {
      "x": -3,
      "y": 1,
      "z": 0,
      "name": "Empty"
    },
    {
      "x": -3,
      "y": 2,
      "z": 0,
      "name": "Empty"
    },
    {
      "x": -3,
      "y": 3,
      "z": 0,
      "name": "Wood_Hardwood_Planks"
    },
    {
      "x": -3,
      "y": 4,
      "z": 0,
      "name": "Empty"
    },
    {
      "x": -3,
      "y": 5,
      "z": 0,
      "name": "Empty"
    },
    {
      "x": -3,
      "y": 6,
      "z": 0,
      "name": "Empty"
    },
    {
      "x": -3,
      "y": 7,
      "z": 0,
      "name": "Wood_Oak_Trunk",
      "support": 15,
      "rotation": 5
    },
    {
      "x": -3,
      "y": 8,
      "z": 0,
      "name": "HyDomum_Shingle__Soil_Clay_Brick__Wood_Hardwood_Planks",
      "rotation": 3
    },
    {
      "x": -3,
      "y": 9,
      "z": 0,
      "name": "Empty"
    },
    {
      "x": -3,
      "y": 10,
      "z": 0,
      "name": "Empty"
    },
    {
      "x": -3,
      "y": 11,
      "z": 0,
      "name": "Empty"
    },
    {
      "x": -3,
      "y": 12,
      "z": 0,
      "name": "Empty"
    },
    {
      "x": -3,
      "y": 13,
      "z": 0,
      "name": "Empty"
    },
    {
      "x": -3,
      "y": -6,
      "z": 1,
      "name": "Rock_Stone_Cobble"
    },
    {
      "x": -3,
      "y": -5,
      "z": 1,
      "name": "Rock_Stone_Brick"
    },
    {
      "x": -3,
      "y": -4,
      "z": 1,
      "name": "Rock_Stone_Cobble"
    },
    {
      "x": -3,
      "y": -3,
      "z": 1,
      "name": "Rock_Stone_Cobble"
    },
    {
      "x": -3,
      "y": -2,
      "z": 1,
      "name": "Rock_Stone_Cobble_Stairs"
    },
    {
      "x": -3,
      "y": -1,
      "z": 1,
      "name": "Empty"
    },
    {
      "x": -3,
      "y": 0,
      "z": 1,
      "name": "Empty"
    },
    {
      "x": -3,
      "y": 1,
      "z": 1,
      "name": "Empty"
    },
    {
      "x": -3,
      "y": 2,
      "z": 1,
      "name": "Wood_Hardwood_Stairs",
      "rotation": 8
    },
    {
      "x": -3,
      "y": 3,
      "z": 1,
      "name": "Wood_Hardwood_Stairs"
    },
    {
      "x": -3,
      "y": 4,
      "z": 1,
      "name": "Empty"
    },
    {
      "x": -3,
      "y": 5,
      "z": 1,
      "name": "Empty"
    },
    {
      "x": -3,
      "y": 6,
      "z": 1,
      "name": "Empty"
    },
    {
      "x": -3,
      "y": 7,
      "z": 1,
      "name": "Wood_Hardwood_Stairs",
      "rotation": 11
    },
    {
      "x": -3,
      "y": 8,
      "z": 1,
      "name": "HyDomum_Shingle__Soil_Clay_Brick__Wood_Hardwood_Planks",
      "rotation": 3
    },
    {
      "x": -3,
      "y": 9,
      "z": 1,
      "name": "Empty"
    },
    {
      "x": -3,
      "y": 10,
      "z": 1,
      "name": "Empty"
    },
    {
      "x": -3,
      "y": 11,
      "z": 1,
      "name": "Empty"
    },
    {
      "x": -3,
      "y": 12,
      "z": 1,
      "name": "Empty"
    },
    {
      "x": -3,
      "y": 13,
      "z": 1,
      "name": "Empty"
    },
    {
      "x": -3,
      "y": -6,
      "z": 2,
      "name": "Rock_Stone_Cobble"
    },
    {
      "x": -3,
      "y": -5,
      "z": 2,
      "name": "Rock_Stone_Brick"
    },
    {
      "x": -3,
      "y": -4,
      "z": 2,
      "name": "Rock_Stone_Cobble"
    },
    {
      "x": -3,
      "y": -3,
      "z": 2,
      "name": "Rock_Stone_Cobble_Stairs"
    },
    {
      "x": -3,
      "y": -2,
      "z": 2,
      "name": "Empty"
    },
    {
      "x": -3,
      "y": -1,
      "z": 2,
      "name": "Empty"
    },
    {
      "x": -3,
      "y": 0,
      "z": 2,
      "name": "Empty"
    },
    {
      "x": -3,
      "y": 1,
      "z": 2,
      "name": "Wood_Hardwood_Stairs",
      "rotation": 8
    },
    {
      "x": -3,
      "y": 2,
      "z": 2,
      "name": "Wood_Hardwood_Stairs"
    },
    {
      "x": -3,
      "y": 3,
      "z": 2,
      "name": "Empty"
    },
    {
      "x": -3,
      "y": 4,
      "z": 2,
      "name": "Empty"
    },
    {
      "x": -3,
      "y": 5,
      "z": 2,
      "name": "Wood_Torch_Wall",
      "rotation": 1
    },
    {
      "x": -3,
      "y": 6,
      "z": 2,
      "name": "Empty"
    },
    {
      "x": -3,
      "y": 7,
      "z": 2,
      "name": "Wood_Hardwood_Stairs",
      "rotation": 11
    },
    {
      "x": -3,
      "y": 8,
      "z": 2,
      "name": "HyDomum_Shingle__Soil_Clay_Brick__Wood_Hardwood_Planks",
      "rotation": 3
    },
    {
      "x": -3,
      "y": 9,
      "z": 2,
      "name": "Empty"
    },
    {
      "x": -3,
      "y": 10,
      "z": 2,
      "name": "Empty"
    },
    {
      "x": -3,
      "y": 11,
      "z": 2,
      "name": "Empty"
    },
    {
      "x": -3,
      "y": 12,
      "z": 2,
      "name": "Empty"
    },
    {
      "x": -3,
      "y": 13,
      "z": 2,
      "name": "Empty"
    },
    {
      "x": -3,
      "y": -6,
      "z": 3,
      "name": "Rock_Stone_Cobble"
    },
    {
      "x": -3,
      "y": -5,
      "z": 3,
      "name": "Rock_Stone_Brick"
    },
    {
      "x": -3,
      "y": -4,
      "z": 3,
      "name": "Rock_Stone_Cobble"
    },
    {
      "x": -3,
      "y": -3,
      "z": 3,
      "name": "Empty"
    },
    {
      "x": -3,
      "y": -2,
      "z": 3,
      "name": "Empty"
    },
    {
      "x": -3,
      "y": -1,
      "z": 3,
      "name": "Empty"
    },
    {
      "x": -3,
      "y": 0,
      "z": 3,
      "name": "Wood_Hardwood_Stairs",
      "rotation": 8
    },
    {
      "x": -3,
      "y": 1,
      "z": 3,
      "name": "Wood_Hardwood_Planks"
    },
    {
      "x": -3,
      "y": 2,
      "z": 3,
      "name": "Empty"
    },
    {
      "x": -3,
      "y": 3,
      "z": 3,
      "name": "Empty"
    },
    {
      "x": -3,
      "y": 4,
      "z": 3,
      "name": "Empty"
    },
    {
      "x": -3,
      "y": 5,
      "z": 3,
      "name": "Empty"
    },
    {
      "x": -3,
      "y": 6,
      "z": 3,
      "name": "Empty"
    },
    {
      "x": -3,
      "y": 7,
      "z": 3,
      "name": "Wood_Hardwood_Stairs",
      "rotation": 11
    },
    {
      "x": -3,
      "y": 8,
      "z": 3,
      "name": "HyDomum_Shingle__Soil_Clay_Smooth_Orange__Wood_Hardwood_Planks",
      "rotation": 3
    },
    {
      "x": -3,
      "y": 9,
      "z": 3,
      "name": "Empty"
    },
    {
      "x": -3,
      "y": 10,
      "z": 3,
      "name": "Empty"
    },
    {
      "x": -3,
      "y": 11,
      "z": 3,
      "name": "Empty"
    },
    {
      "x": -3,
      "y": 12,
      "z": 3,
      "name": "Empty"
    },
    {
      "x": -3,
      "y": 13,
      "z": 3,
      "name": "Empty"
    },
    {
      "x": -3,
      "y": -6,
      "z": 4,
      "name": "Rock_Stone_Cobble"
    },
    {
      "x": -3,
      "y": -5,
      "z": 4,
      "name": "Rock_Stone_Cobble"
    },
    {
      "x": -3,
      "y": -4,
      "z": 4,
      "name": "Rock_Stone_Cobble"
    },
    {
      "x": -3,
      "y": -3,
      "z": 4,
      "name": "Rock_Stone_Cobble"
    },
    {
      "x": -3,
      "y": -2,
      "z": 4,
      "name": "Rock_Stone_Brick"
    },
    {
      "x": -3,
      "y": -1,
      "z": 4,
      "name": "Rock_Stone_Brick"
    },
    {
      "x": -3,
      "y": 0,
      "z": 4,
      "name": "Rock_Stone_Brick"
    },
    {
      "x": -3,
      "y": 1,
      "z": 4,
      "name": "Rock_Stone_Brick"
    },
    {
      "x": -3,
      "y": 2,
      "z": 4,
      "name": "Rock_Stone_Brick"
    },
    {
      "x": -3,
      "y": 3,
      "z": 4,
      "name": "Wood_Oak_Trunk",
      "support": 15,
      "rotation": 5
    },
    {
      "x": -3,
      "y": 4,
      "z": 4,
      "name": "Wood_Hardwood_Planks"
    },
    {
      "x": -3,
      "y": 5,
      "z": 4,
      "name": "HyDomum_TimberFrame_OneCrossedLr__Wood_Hardwood_Planks__Soil_Clay_Smooth_White"
    },
    {
      "x": -3,
      "y": 6,
      "z": 4,
      "name": "HyDomum_TimberFrame_OneCrossedLr__Wood_Hardwood_Planks__Soil_Clay_Smooth_White"
    },
    {
      "x": -3,
      "y": 7,
      "z": 4,
      "name": "Wood_Oak_Trunk",
      "support": 15,
      "rotation": 5
    },
    {
      "x": -3,
      "y": 8,
      "z": 4,
      "name": "HyDomum_Shingle__Soil_Clay_Smooth_Orange__Wood_Hardwood_Planks",
      "rotation": 3
    },
    {
      "x": -3,
      "y": 9,
      "z": 4,
      "name": "Empty"
    },
    {
      "x": -3,
      "y": 10,
      "z": 4,
      "name": "Empty"
    },
    {
      "x": -3,
      "y": 11,
      "z": 4,
      "name": "Empty"
    },
    {
      "x": -3,
      "y": 12,
      "z": 4,
      "name": "Empty"
    },
    {
      "x": -3,
      "y": 13,
      "z": 4,
      "name": "Empty"
    },
    {
      "x": -3,
      "y": -6,
      "z": 5,
      "name": "Rock_Stone_Cobble"
    },
    {
      "x": -3,
      "y": -5,
      "z": 5,
      "name": "Rock_Stone_Cobble"
    },
    {
      "x": -3,
      "y": -4,
      "z": 5,
      "name": "Rock_Stone_Cobble"
    },
    {
      "x": -3,
      "y": -3,
      "z": 5,
      "name": "Rock_Stone_Cobble"
    },
    {
      "x": -3,
      "y": -2,
      "z": 5,
      "name": "Rock_Stone_Cobble"
    },
    {
      "x": -3,
      "y": -1,
      "z": 5,
      "name": "Rock_Stone_Cobble_Stairs",
      "rotation": 3
    },
    {
      "x": -3,
      "y": 0,
      "z": 5,
      "name": "Empty"
    },
    {
      "x": -3,
      "y": 1,
      "z": 5,
      "name": "Wood_Torch_Wall"
    },
    {
      "x": -3,
      "y": 2,
      "z": 5,
      "name": "Rock_Stone_Brick_Stairs",
      "rotation": 10
    },
    {
      "x": -3,
      "y": 3,
      "z": 5,
      "name": "Wood_Hardwood_Planks"
    },
    {
      "x": -3,
      "y": 4,
      "z": 5,
      "name": "Wood_Hardwood_Stairs",
      "rotation": 11
    },
    {
      "x": -3,
      "y": 5,
      "z": 5,
      "name": "Furniture_Crude_Torch"
    },
    {
      "x": -3,
      "y": 6,
      "z": 5,
      "name": "Empty"
    },
    {
      "x": -3,
      "y": 7,
      "z": 5,
      "name": "Wood_Hardwood_Stairs",
      "rotation": 11
    },
    {
      "x": -3,
      "y": 8,
      "z": 5,
      "name": "HyDomum_Shingle__Soil_Clay_Brick__Wood_Hardwood_Planks",
      "rotation": 3
    },
    {
      "x": -3,
      "y": 9,
      "z": 5,
      "name": "Empty"
    },
    {
      "x": -3,
      "y": 10,
      "z": 5,
      "name": "Empty"
    },
    {
      "x": -3,
      "y": 11,
      "z": 5,
      "name": "Empty"
    },
    {
      "x": -3,
      "y": 12,
      "z": 5,
      "name": "Empty"
    },
    {
      "x": -3,
      "y": 13,
      "z": 5,
      "name": "Empty"
    },
    {
      "x": -3,
      "y": -6,
      "z": 6,
      "name": "Rock_Stone_Cobble"
    },
    {
      "x": -3,
      "y": -5,
      "z": 6,
      "name": "Rock_Stone_Cobble"
    },
    {
      "x": -3,
      "y": -4,
      "z": 6,
      "name": "Rock_Stone_Cobble"
    },
    {
      "x": -3,
      "y": -3,
      "z": 6,
      "name": "Rock_Stone_Cobble"
    },
    {
      "x": -3,
      "y": -2,
      "z": 6,
      "name": "Rock_Stone_Cobble"
    },
    {
      "x": -3,
      "y": -1,
      "z": 6,
      "name": "Rock_Stone_Cobble_Stairs",
      "rotation": 3
    },
    {
      "x": -3,
      "y": 0,
      "z": 6,
      "name": "Empty"
    },
    {
      "x": -3,
      "y": 1,
      "z": 6,
      "name": "Empty"
    },
    {
      "x": -3,
      "y": 2,
      "z": 6,
      "name": "Rock_Stone_Brick_Half",
      "rotation": 8
    },
    {
      "x": -3,
      "y": 3,
      "z": 6,
      "name": "Wood_Hardwood_Planks"
    },
    {
      "x": -3,
      "y": 4,
      "z": 6,
      "name": "Empty"
    },
    {
      "x": -3,
      "y": 5,
      "z": 6,
      "name": "Empty"
    },
    {
      "x": -3,
      "y": 6,
      "z": 6,
      "name": "Empty"
    },
    {
      "x": -3,
      "y": 7,
      "z": 6,
      "name": "Wood_Hardwood_Stairs",
      "rotation": 11
    },
    {
      "x": -3,
      "y": 8,
      "z": 6,
      "name": "HyDomum_Shingle__Soil_Clay_Brick__Wood_Hardwood_Planks",
      "rotation": 3
    },
    {
      "x": -3,
      "y": 9,
      "z": 6,
      "name": "Empty"
    },
    {
      "x": -3,
      "y": 10,
      "z": 6,
      "name": "Empty"
    },
    {
      "x": -3,
      "y": 11,
      "z": 6,
      "name": "Empty"
    },
    {
      "x": -3,
      "y": 12,
      "z": 6,
      "name": "Empty"
    },
    {
      "x": -3,
      "y": 13,
      "z": 6,
      "name": "Empty"
    },
    {
      "x": -3,
      "y": -6,
      "z": 7,
      "name": "Rock_Stone_Cobble"
    },
    {
      "x": -3,
      "y": -5,
      "z": 7,
      "name": "Rock_Stone_Cobble"
    },
    {
      "x": -3,
      "y": -4,
      "z": 7,
      "name": "Rock_Stone_Cobble"
    },
    {
      "x": -3,
      "y": -3,
      "z": 7,
      "name": "Rock_Stone_Cobble"
    },
    {
      "x": -3,
      "y": -2,
      "z": 7,
      "name": "Rock_Stone_Cobble"
    },
    {
      "x": -3,
      "y": -1,
      "z": 7,
      "name": "Rock_Stone_Cobble_Stairs",
      "rotation": 3
    },
    {
      "x": -3,
      "y": 0,
      "z": 7,
      "name": "Empty"
    },
    {
      "x": -3,
      "y": 1,
      "z": 7,
      "name": "Wood_Torch_Wall",
      "rotation": 2
    },
    {
      "x": -3,
      "y": 2,
      "z": 7,
      "name": "Rock_Stone_Brick_Stairs",
      "rotation": 8
    },
    {
      "x": -3,
      "y": 3,
      "z": 7,
      "name": "Wood_Hardwood_Planks"
    },
    {
      "x": -3,
      "y": 4,
      "z": 7,
      "name": "Empty"
    },
    {
      "x": -3,
      "y": 5,
      "z": 7,
      "name": "Empty"
    },
    {
      "x": -3,
      "y": 6,
      "z": 7,
      "name": "Empty"
    },
    {
      "x": -3,
      "y": 7,
      "z": 7,
      "name": "Wood_Hardwood_Stairs",
      "rotation": 11
    },
    {
      "x": -3,
      "y": 8,
      "z": 7,
      "name": "HyDomum_Shingle__Soil_Clay_Smooth_Orange__Wood_Hardwood_Planks",
      "rotation": 3
    },
    {
      "x": -3,
      "y": 9,
      "z": 7,
      "name": "Empty"
    },
    {
      "x": -3,
      "y": 10,
      "z": 7,
      "name": "Empty"
    },
    {
      "x": -3,
      "y": 11,
      "z": 7,
      "name": "Empty"
    },
    {
      "x": -3,
      "y": 12,
      "z": 7,
      "name": "Empty"
    },
    {
      "x": -3,
      "y": 13,
      "z": 7,
      "name": "Empty"
    },
    {
      "x": -3,
      "y": -6,
      "z": 8,
      "name": "Rock_Stone_Cobble"
    },
    {
      "x": -3,
      "y": -5,
      "z": 8,
      "name": "Rock_Stone_Cobble"
    },
    {
      "x": -3,
      "y": -4,
      "z": 8,
      "name": "Rock_Stone_Cobble"
    },
    {
      "x": -3,
      "y": -3,
      "z": 8,
      "name": "Rock_Stone_Cobble"
    },
    {
      "x": -3,
      "y": -2,
      "z": 8,
      "name": "Rock_Stone_Cobble"
    },
    {
      "x": -3,
      "y": -1,
      "z": 8,
      "name": "Rock_Stone_Brick"
    },
    {
      "x": -3,
      "y": 0,
      "z": 8,
      "name": "Rock_Stone_Brick"
    },
    {
      "x": -3,
      "y": 1,
      "z": 8,
      "name": "Rock_Stone_Brick"
    },
    {
      "x": -3,
      "y": 2,
      "z": 8,
      "name": "Rock_Stone_Brick"
    },
    {
      "x": -3,
      "y": 3,
      "z": 8,
      "name": "Wood_Hardwood_Planks"
    },
    {
      "x": -3,
      "y": 4,
      "z": 8,
      "name": "Wood_Oak_Trunk",
      "support": 15,
      "rotation": 5
    },
    {
      "x": -3,
      "y": 5,
      "z": 8,
      "name": "Furniture_Crude_Chest_Small",
      "rotation": 1,
      "components": {
        "Components": {
          "ItemContainerBlock": {
            "Capacity": 18
          }
        }
      }
    },
    {
      "x": -3,
      "y": 6,
      "z": 8,
      "name": "Empty"
    },
    {
      "x": -3,
      "y": 7,
      "z": 8,
      "name": "Wood_Hardwood_Stairs",
      "rotation": 11
    },
    {
      "x": -3,
      "y": 8,
      "z": 8,
      "name": "HyDomum_Shingle__Soil_Clay_Brick__Wood_Hardwood_Planks",
      "rotation": 3
    },
    {
      "x": -3,
      "y": 9,
      "z": 8,
      "name": "Empty"
    },
    {
      "x": -3,
      "y": 10,
      "z": 8,
      "name": "Empty"
    },
    {
      "x": -3,
      "y": 11,
      "z": 8,
      "name": "Empty"
    },
    {
      "x": -3,
      "y": 12,
      "z": 8,
      "name": "Empty"
    },
    {
      "x": -3,
      "y": 13,
      "z": 8,
      "name": "Empty"
    },
    {
      "x": -3,
      "y": 0,
      "z": 9,
      "name": "Empty"
    },
    {
      "x": -3,
      "y": 1,
      "z": 9,
      "name": "Empty"
    },
    {
      "x": -3,
      "y": 2,
      "z": 9,
      "name": "Rock_Stone_Cobble_Stairs",
      "rotation": 10
    },
    {
      "x": -3,
      "y": 3,
      "z": 9,
      "name": "Wood_Oak_Trunk",
      "support": 15,
      "rotation": 5
    },
    {
      "x": -3,
      "y": 4,
      "z": 9,
      "name": "HyDomum_TimberFrame_Plain__Wood_Hardwood_Planks__Wood_Hardwood_Planks"
    },
    {
      "x": -3,
      "y": 5,
      "z": 9,
      "name": "HyDomum_TimberFrame_OneCrossedLr__Wood_Hardwood_Planks__Soil_Clay_Smooth_White"
    },
    {
      "x": -3,
      "y": 6,
      "z": 9,
      "name": "HyDomum_TimberFrame_OneCrossedLr__Wood_Hardwood_Planks__Soil_Clay_Smooth_White"
    },
    {
      "x": -3,
      "y": 7,
      "z": 9,
      "name": "Wood_Oak_Trunk",
      "support": 15,
      "rotation": 5
    },
    {
      "x": -3,
      "y": 8,
      "z": 9,
      "name": "HyDomum_Shingle__Soil_Clay_Brick__Wood_Hardwood_Planks",
      "rotation": 3
    },
    {
      "x": -3,
      "y": 9,
      "z": 9,
      "name": "Empty"
    },
    {
      "x": -3,
      "y": 10,
      "z": 9,
      "name": "Empty"
    },
    {
      "x": -3,
      "y": 11,
      "z": 9,
      "name": "Empty"
    },
    {
      "x": -3,
      "y": 12,
      "z": 9,
      "name": "Empty"
    },
    {
      "x": -3,
      "y": 13,
      "z": 9,
      "name": "Empty"
    },
    {
      "x": -3,
      "y": 0,
      "z": 10,
      "name": "Empty"
    },
    {
      "x": -3,
      "y": 1,
      "z": 10,
      "name": "Empty"
    },
    {
      "x": -3,
      "y": 2,
      "z": 10,
      "name": "Wood_Hardwood_Planks"
    },
    {
      "x": -3,
      "y": 3,
      "z": 10,
      "name": "Rock_Stone_Cobble_Half"
    },
    {
      "x": -3,
      "y": 4,
      "z": 10,
      "name": "Empty"
    },
    {
      "x": -3,
      "y": 5,
      "z": 10,
      "name": "Empty"
    },
    {
      "x": -3,
      "y": 6,
      "z": 10,
      "name": "Wood_Hardwood_Planks_Half",
      "rotation": 8
    },
    {
      "x": -3,
      "y": 7,
      "z": 10,
      "name": "Wood_Oak_Trunk",
      "support": 15
    },
    {
      "x": -3,
      "y": 8,
      "z": 10,
      "name": "HyDomum_Shingle__Soil_Clay_Smooth_Orange__Wood_Hardwood_Planks",
      "rotation": 3
    },
    {
      "x": -3,
      "y": 9,
      "z": 10,
      "name": "Empty"
    },
    {
      "x": -3,
      "y": 10,
      "z": 10,
      "name": "Empty"
    },
    {
      "x": -3,
      "y": 11,
      "z": 10,
      "name": "Empty"
    },
    {
      "x": -3,
      "y": 12,
      "z": 10,
      "name": "Empty"
    },
    {
      "x": -3,
      "y": 13,
      "z": 10,
      "name": "Empty"
    },
    {
      "x": -3,
      "y": 0,
      "z": 11,
      "name": "Empty"
    },
    {
      "x": -3,
      "y": 1,
      "z": 11,
      "name": "Empty"
    },
    {
      "x": -3,
      "y": 2,
      "z": 11,
      "name": "Empty"
    },
    {
      "x": -3,
      "y": 3,
      "z": 11,
      "name": "Empty"
    },
    {
      "x": -3,
      "y": 4,
      "z": 11,
      "name": "Empty"
    },
    {
      "x": -3,
      "y": 5,
      "z": 11,
      "name": "Empty"
    },
    {
      "x": -3,
      "y": 6,
      "z": 11,
      "name": "Empty"
    },
    {
      "x": -3,
      "y": 7,
      "z": 11,
      "name": "Empty"
    },
    {
      "x": -3,
      "y": 8,
      "z": 11,
      "name": "Empty"
    },
    {
      "x": -3,
      "y": 9,
      "z": 11,
      "name": "Empty"
    },
    {
      "x": -3,
      "y": 10,
      "z": 11,
      "name": "Empty"
    },
    {
      "x": -3,
      "y": 11,
      "z": 11,
      "name": "Empty"
    },
    {
      "x": -3,
      "y": 12,
      "z": 11,
      "name": "Empty"
    },
    {
      "x": -3,
      "y": 13,
      "z": 11,
      "name": "Empty"
    },
    {
      "x": -2,
      "y": 0,
      "z": -2,
      "name": "Empty"
    },
    {
      "x": -2,
      "y": 1,
      "z": -2,
      "name": "Empty"
    },
    {
      "x": -2,
      "y": 2,
      "z": -2,
      "name": "Empty"
    },
    {
      "x": -2,
      "y": 3,
      "z": -2,
      "name": "Wood_Oak_Trunk",
      "support": 15,
      "rotation": 5
    },
    {
      "x": -2,
      "y": 4,
      "z": -2,
      "name": "HyDomum_TimberFrame_Plain__Wood_Hardwood_Planks__Wood_Hardwood_Planks"
    },
    {
      "x": -2,
      "y": 5,
      "z": -2,
      "name": "HyDomum_TimberFrame_OneCrossedLr__Wood_Hardwood_Planks__Soil_Clay_Smooth_White"
    },
    {
      "x": -2,
      "y": 6,
      "z": -2,
      "name": "HyDomum_TimberFrame_OneCrossedLr__Wood_Hardwood_Planks__Soil_Clay_Smooth_White"
    },
    {
      "x": -2,
      "y": 7,
      "z": -2,
      "name": "Wood_Oak_Trunk",
      "support": 15,
      "rotation": 5
    },
    {
      "x": -2,
      "y": 8,
      "z": -2,
      "name": "Wood_Oak_Trunk",
      "support": 15
    },
    {
      "x": -2,
      "y": 9,
      "z": -2,
      "name": "HyDomum_Shingle__Soil_Clay_Brick__Wood_Hardwood_Planks",
      "rotation": 3
    },
    {
      "x": -2,
      "y": 10,
      "z": -2,
      "name": "Empty"
    },
    {
      "x": -2,
      "y": 11,
      "z": -2,
      "name": "Empty"
    },
    {
      "x": -2,
      "y": 12,
      "z": -2,
      "name": "Empty"
    },
    {
      "x": -2,
      "y": 13,
      "z": -2,
      "name": "Empty"
    },
    {
      "x": -2,
      "y": -6,
      "z": -1,
      "name": "Rock_Stone_Brick"
    },
    {
      "x": -2,
      "y": -5,
      "z": -1,
      "name": "Rock_Stone_Cobble"
    },
    {
      "x": -2,
      "y": -4,
      "z": -1,
      "name": "Rock_Stone_Cobble"
    },
    {
      "x": -2,
      "y": -3,
      "z": -1,
      "name": "Rock_Stone_Cobble"
    },
    {
      "x": -2,
      "y": -2,
      "z": -1,
      "name": "Rock_Stone_Cobble"
    },
    {
      "x": -2,
      "y": -1,
      "z": -1,
      "name": "Rock_Stone_Cobble"
    },
    {
      "x": -2,
      "y": 0,
      "z": -1,
      "name": "Rock_Stone_Cobble"
    },
    {
      "x": -2,
      "y": 1,
      "z": -1,
      "name": "Rock_Stone_Cobble"
    },
    {
      "x": -2,
      "y": 2,
      "z": -1,
      "name": "Rock_Stone_Cobble"
    },
    {
      "x": -2,
      "y": 3,
      "z": -1,
      "name": "Wood_Oak_Trunk",
      "support": 15,
      "rotation": 5
    },
    {
      "x": -2,
      "y": 4,
      "z": -1,
      "name": "Empty"
    },
    {
      "x": -2,
      "y": 5,
      "z": -1,
      "name": "Empty"
    },
    {
      "x": -2,
      "y": 6,
      "z": -1,
      "name": "Empty"
    },
    {
      "x": -2,
      "y": 7,
      "z": -1,
      "name": "Wood_Oak_Trunk",
      "support": 15,
      "rotation": 4
    },
    {
      "x": -2,
      "y": 8,
      "z": -1,
      "name": "HyDomum_TimberFrame_Plain__Wood_Hardwood_Planks__Soil_Clay_Smooth_White"
    },
    {
      "x": -2,
      "y": 9,
      "z": -1,
      "name": "HyDomum_Shingle__Soil_Clay_Brick__Wood_Hardwood_Planks",
      "rotation": 3
    },
    {
      "x": -2,
      "y": 10,
      "z": -1,
      "name": "Empty"
    },
    {
      "x": -2,
      "y": 11,
      "z": -1,
      "name": "Empty"
    },
    {
      "x": -2,
      "y": 12,
      "z": -1,
      "name": "Empty"
    },
    {
      "x": -2,
      "y": 13,
      "z": -1,
      "name": "Empty"
    },
    {
      "x": -2,
      "y": -6,
      "z": 0,
      "name": "Rock_Stone_Brick"
    },
    {
      "x": -2,
      "y": -5,
      "z": 0,
      "name": "*HyDomum_Wall__Rock_Stone_Cobble_State_Definitions_Corner",
      "rotation": 1
    },
    {
      "x": -2,
      "y": -4,
      "z": 0,
      "name": "*HyDomum_Fence__Wood_Hardwood_Planks_State_Definitions_End",
      "rotation": 2
    },
    {
      "x": -2,
      "y": -3,
      "z": 0,
      "name": "*HyDomum_Fence__Wood_Hardwood_Planks_State_Definitions_End",
      "rotation": 2
    },
    {
      "x": -2,
      "y": -2,
      "z": 0,
      "name": "Rock_Stone_Brick"
    },
    {
      "x": -2,
      "y": -1,
      "z": 0,
      "name": "Rock_Stone_Brick"
    },
    {
      "x": -2,
      "y": 0,
      "z": 0,
      "name": "Empty"
    },
    {
      "x": -2,
      "y": 1,
      "z": 0,
      "name": "Empty"
    },
    {
      "x": -2,
      "y": 2,
      "z": 0,
      "name": "Empty"
    },
    {
      "x": -2,
      "y": 3,
      "z": 0,
      "name": "Wood_Oak_Trunk",
      "support": 15,
      "rotation": 5
    },
    {
      "x": -2,
      "y": 4,
      "z": 0,
      "name": "Wood_Oak_Trunk",
      "support": 15
    },
    {
      "x": -2,
      "y": 5,
      "z": 0,
      "name": "Wood_Oak_Trunk",
      "support": 15
    },
    {
      "x": -2,
      "y": 6,
      "z": 0,
      "name": "Wood_Oak_Trunk",
      "support": 15
    },
    {
      "x": -2,
      "y": 7,
      "z": 0,
      "name": "Wood_Oak_Trunk",
      "support": 15
    },
    {
      "x": -2,
      "y": 8,
      "z": 0,
      "name": "Wood_Oak_Trunk",
      "support": 15
    },
    {
      "x": -2,
      "y": 9,
      "z": 0,
      "name": "HyDomum_Shingle__Soil_Clay_Smooth_Orange__Wood_Hardwood_Planks",
      "rotation": 3
    },
    {
      "x": -2,
      "y": 10,
      "z": 0,
      "name": "Empty"
    },
    {
      "x": -2,
      "y": 11,
      "z": 0,
      "name": "Empty"
    },
    {
      "x": -2,
      "y": 12,
      "z": 0,
      "name": "Empty"
    },
    {
      "x": -2,
      "y": 13,
      "z": 0,
      "name": "Empty"
    },
    {
      "x": -2,
      "y": -6,
      "z": 1,
      "name": "Rock_Stone_Cobble"
    },
    {
      "x": -2,
      "y": -5,
      "z": 1,
      "name": "*HyDomum_Wall__Rock_Stone_Cobble_State_Definitions_T",
      "rotation": 1
    },
    {
      "x": -2,
      "y": -4,
      "z": 1,
      "name": "HyDomum_Fence__Wood_Hardwood_Planks",
      "rotation": 1
    },
    {
      "x": -2,
      "y": -3,
      "z": 1,
      "name": "HyDomum_Fence__Wood_Hardwood_Planks",
      "rotation": 1
    },
    {
      "x": -2,
      "y": -2,
      "z": 1,
      "name": "Rock_Stone_Brick"
    },
    {
      "x": -2,
      "y": -1,
      "z": 1,
      "name": "Rock_Stone_Brick"
    },
    {
      "x": -2,
      "y": 0,
      "z": 1,
      "name": "Wood_Hardwood_Stairs",
      "rotation": 2
    },
    {
      "x": -2,
      "y": 1,
      "z": 1,
      "name": "Empty"
    },
    {
      "x": -2,
      "y": 2,
      "z": 1,
      "name": "Empty"
    },
    {
      "x": -2,
      "y": 3,
      "z": 1,
      "name": "Empty"
    },
    {
      "x": -2,
      "y": 4,
      "z": 1,
      "name": "Wood_Hardwood_Stairs",
      "rotation": 9
    },
    {
      "x": -2,
      "y": 5,
      "z": 1,
      "name": "HyDomum_TimberFrame_OneCrossedLr__Wood_Hardwood_Planks__Soil_Clay_Smooth_White"
    },
    {
      "x": -2,
      "y": 6,
      "z": 1,
      "name": "HyDomum_TimberFrame_OneCrossedLr__Wood_Hardwood_Planks__Soil_Clay_Smooth_White"
    },
    {
      "x": -2,
      "y": 7,
      "z": 1,
      "name": "Wood_Oak_Trunk",
      "support": 15,
      "rotation": 4
    },
    {
      "x": -2,
      "y": 8,
      "z": 1,
      "name": "HyDomum_TimberFrame_Plain__Wood_Hardwood_Planks__Soil_Clay_Smooth_White"
    },
    {
      "x": -2,
      "y": 9,
      "z": 1,
      "name": "HyDomum_Shingle__Soil_Clay_Smooth_Orange__Wood_Hardwood_Planks",
      "rotation": 3
    },
    {
      "x": -2,
      "y": 10,
      "z": 1,
      "name": "Empty"
    },
    {
      "x": -2,
      "y": 11,
      "z": 1,
      "name": "Empty"
    },
    {
      "x": -2,
      "y": 12,
      "z": 1,
      "name": "Empty"
    },
    {
      "x": -2,
      "y": 13,
      "z": 1,
      "name": "Empty"
    },
    {
      "x": -2,
      "y": -6,
      "z": 2,
      "name": "Rock_Stone_Cobble"
    },
    {
      "x": -2,
      "y": -5,
      "z": 2,
      "name": "*HyDomum_Wall__Rock_Stone_Cobble_State_Definitions_T",
      "rotation": 1
    },
    {
      "x": -2,
      "y": -4,
      "z": 2,
      "name": "*HyDomum_Fence__Wood_Hardwood_Planks_State_Definitions_Corner",
      "rotation": 2
    },
    {
      "x": -2,
      "y": -3,
      "z": 2,
      "name": "*HyDomum_Fence__Wood_Hardwood_Planks_State_Definitions_Corner",
      "rotation": 2
    },
    {
      "x": -2,
      "y": -2,
      "z": 2,
      "name": "Rock_Stone_Brick"
    },
    {
      "x": -2,
      "y": -1,
      "z": 2,
      "name": "Rock_Stone_Brick"
    },
    {
      "x": -2,
      "y": 0,
      "z": 2,
      "name": "Rock_Stone_Cobble"
    },
    {
      "x": -2,
      "y": 1,
      "z": 2,
      "name": "Wood_Hardwood_Stairs",
      "rotation": 2
    },
    {
      "x": -2,
      "y": 2,
      "z": 2,
      "name": "Empty"
    },
    {
      "x": -2,
      "y": 3,
      "z": 2,
      "name": "Empty"
    },
    {
      "x": -2,
      "y": 4,
      "z": 2,
      "name": "Wood_Hardwood_Stairs",
      "rotation": 9
    },
    {
      "x": -2,
      "y": 5,
      "z": 2,
      "name": "HyDomum_TimberFrame_Plain__Wood_Hardwood_Planks__Soil_Clay_Smooth_White"
    },
    {
      "x": -2,
      "y": 6,
      "z": 2,
      "name": "HyDomum_TimberFrame_Plain__Wood_Hardwood_Planks__Soil_Clay_Smooth_White"
    },
    {
      "x": -2,
      "y": 7,
      "z": 2,
      "name": "Wood_Oak_Trunk",
      "support": 15,
      "rotation": 4
    },
    {
      "x": -2,
      "y": 8,
      "z": 2,
      "name": "HyDomum_TimberFrame_Plain__Wood_Hardwood_Planks__Soil_Clay_Smooth_White"
    },
    {
      "x": -2,
      "y": 9,
      "z": 2,
      "name": "HyDomum_Shingle__Soil_Clay_Brick__Wood_Hardwood_Planks",
      "rotation": 3
    },
    {
      "x": -2,
      "y": 10,
      "z": 2,
      "name": "Empty"
    },
    {
      "x": -2,
      "y": 11,
      "z": 2,
      "name": "Empty"
    },
    {
      "x": -2,
      "y": 12,
      "z": 2,
      "name": "Empty"
    },
    {
      "x": -2,
      "y": 13,
      "z": 2,
      "name": "Empty"
    },
    {
      "x": -2,
      "y": -6,
      "z": 3,
      "name": "Rock_Stone_Cobble"
    },
    {
      "x": -2,
      "y": -5,
      "z": 3,
      "name": "Rock_Stone_Brick"
    },
    {
      "x": -2,
      "y": -4,
      "z": 3,
      "name": "Rock_Stone_Cobble_Stairs",
      "rotation": 1
    },
    {
      "x": -2,
      "y": -3,
      "z": 3,
      "name": "Empty"
    },
    {
      "x": -2,
      "y": -2,
      "z": 3,
      "name": "Empty"
    },
    {
      "x": -2,
      "y": -1,
      "z": 3,
      "name": "Rock_Stone_Brick"
    },
    {
      "x": -2,
      "y": 0,
      "z": 3,
      "name": "Rock_Stone_Cobble"
    },
    {
      "x": -2,
      "y": 1,
      "z": 3,
      "name": "Wood_Hardwood_Planks"
    },
    {
      "x": -2,
      "y": 2,
      "z": 3,
      "name": "Empty"
    },
    {
      "x": -2,
      "y": 3,
      "z": 3,
      "name": "Empty"
    },
    {
      "x": -2,
      "y": 4,
      "z": 3,
      "name": "Wood_Hardwood_Stairs",
      "rotation": 9
    },
    {
      "x": -2,
      "y": 5,
      "z": 3,
      "name": "HyDomum_TimberFrame_OneCrossedRl__Wood_Hardwood_Planks__Soil_Clay_Smooth_White"
    },
    {
      "x": -2,
      "y": 6,
      "z": 3,
      "name": "HyDomum_TimberFrame_OneCrossedRl__Wood_Hardwood_Planks__Soil_Clay_Smooth_White"
    },
    {
      "x": -2,
      "y": 7,
      "z": 3,
      "name": "Wood_Oak_Trunk",
      "support": 15,
      "rotation": 4
    },
    {
      "x": -2,
      "y": 8,
      "z": 3,
      "name": "HyDomum_TimberFrame_Plain__Wood_Hardwood_Planks__Soil_Clay_Smooth_White"
    },
    {
      "x": -2,
      "y": 9,
      "z": 3,
      "name": "HyDomum_Shingle__Soil_Clay_Brick__Wood_Hardwood_Planks",
      "rotation": 3
    },
    {
      "x": -2,
      "y": 10,
      "z": 3,
      "name": "Empty"
    },
    {
      "x": -2,
      "y": 11,
      "z": 3,
      "name": "Empty"
    },
    {
      "x": -2,
      "y": 12,
      "z": 3,
      "name": "Empty"
    },
    {
      "x": -2,
      "y": 13,
      "z": 3,
      "name": "Empty"
    },
    {
      "x": -2,
      "y": -6,
      "z": 4,
      "name": "Rock_Stone_Brick"
    },
    {
      "x": -2,
      "y": -5,
      "z": 4,
      "name": "Rock_Stone_Cobble"
    },
    {
      "x": -2,
      "y": -4,
      "z": 4,
      "name": "Rock_Stone_Cobble"
    },
    {
      "x": -2,
      "y": -3,
      "z": 4,
      "name": "Rock_Stone_Cobble"
    },
    {
      "x": -2,
      "y": -2,
      "z": 4,
      "name": "Rock_Stone_Brick"
    },
    {
      "x": -2,
      "y": -1,
      "z": 4,
      "name": "Rock_Stone_Brick"
    },
    {
      "x": -2,
      "y": 0,
      "z": 4,
      "name": "Rock_Stone_Cobble"
    },
    {
      "x": -2,
      "y": 1,
      "z": 4,
      "name": "Rock_Stone_Cobble"
    },
    {
      "x": -2,
      "y": 2,
      "z": 4,
      "name": "Rock_Stone_Cobble"
    },
    {
      "x": -2,
      "y": 3,
      "z": 4,
      "name": "Wood_Oak_Trunk",
      "support": 15,
      "rotation": 5
    },
    {
      "x": -2,
      "y": 4,
      "z": 4,
      "name": "Wood_Oak_Trunk",
      "support": 15
    },
    {
      "x": -2,
      "y": 5,
      "z": 4,
      "name": "Wood_Oak_Trunk",
      "support": 15
    },
    {
      "x": -2,
      "y": 6,
      "z": 4,
      "name": "Wood_Oak_Trunk",
      "support": 15
    },
    {
      "x": -2,
      "y": 7,
      "z": 4,
      "name": "Wood_Oak_Trunk",
      "support": 15
    },
    {
      "x": -2,
      "y": 8,
      "z": 4,
      "name": "Wood_Oak_Trunk",
      "support": 15
    },
    {
      "x": -2,
      "y": 9,
      "z": 4,
      "name": "HyDomum_Shingle__Soil_Clay_Brick__Wood_Hardwood_Planks",
      "rotation": 3
    },
    {
      "x": -2,
      "y": 10,
      "z": 4,
      "name": "Empty"
    },
    {
      "x": -2,
      "y": 11,
      "z": 4,
      "name": "Empty"
    },
    {
      "x": -2,
      "y": 12,
      "z": 4,
      "name": "Empty"
    },
    {
      "x": -2,
      "y": 13,
      "z": 4,
      "name": "Empty"
    },
    {
      "x": -2,
      "y": -6,
      "z": 5,
      "name": "Rock_Stone_Cobble"
    },
    {
      "x": -2,
      "y": -5,
      "z": 5,
      "name": "Rock_Stone_Cobble"
    },
    {
      "x": -2,
      "y": -4,
      "z": 5,
      "name": "Rock_Stone_Cobble"
    },
    {
      "x": -2,
      "y": -3,
      "z": 5,
      "name": "Rock_Stone_Cobble"
    },
    {
      "x": -2,
      "y": -2,
      "z": 5,
      "name": "Rock_Stone_Cobble"
    },
    {
      "x": -2,
      "y": -1,
      "z": 5,
      "name": "Rock_Stone_Cobble"
    },
    {
      "x": -2,
      "y": 0,
      "z": 5,
      "name": "Empty"
    },
    {
      "x": -2,
      "y": 1,
      "z": 5,
      "name": "Empty"
    },
    {
      "x": -2,
      "y": 2,
      "z": 5,
      "name": "Empty"
    },
    {
      "x": -2,
      "y": 3,
      "z": 5,
      "name": "Wood_Hardwood_Planks"
    },
    {
      "x": -2,
      "y": 4,
      "z": 5,
      "name": "Wood_Hardwood_Stairs",
      "rotation": 9
    },
    {
      "x": -2,
      "y": 5,
      "z": 5,
      "name": "HyVanilla_Flower_Pot_Orange"
    },
    {
      "x": -2,
      "y": 6,
      "z": 5,
      "name": "Empty"
    },
    {
      "x": -2,
      "y": 7,
      "z": 5,
      "name": "Empty"
    },
    {
      "x": -2,
      "y": 8,
      "z": 5,
      "name": "Wood_Hardwood_Stairs",
      "rotation": 11
    },
    {
      "x": -2,
      "y": 9,
      "z": 5,
      "name": "HyDomum_Shingle__Soil_Clay_Brick__Wood_Hardwood_Planks",
      "rotation": 3
    },
    {
      "x": -2,
      "y": 10,
      "z": 5,
      "name": "Empty"
    },
    {
      "x": -2,
      "y": 11,
      "z": 5,
      "name": "Empty"
    },
    {
      "x": -2,
      "y": 12,
      "z": 5,
      "name": "Empty"
    },
    {
      "x": -2,
      "y": 13,
      "z": 5,
      "name": "Empty"
    },
    {
      "x": -2,
      "y": -6,
      "z": 6,
      "name": "Rock_Stone_Cobble"
    },
    {
      "x": -2,
      "y": -5,
      "z": 6,
      "name": "Rock_Stone_Cobble"
    },
    {
      "x": -2,
      "y": -4,
      "z": 6,
      "name": "Rock_Stone_Cobble"
    },
    {
      "x": -2,
      "y": -3,
      "z": 6,
      "name": "Rock_Stone_Cobble"
    },
    {
      "x": -2,
      "y": -2,
      "z": 6,
      "name": "Soil_Dirt"
    },
    {
      "x": -2,
      "y": -1,
      "z": 6,
      "name": "Soil_Gravel"
    },
    {
      "x": -2,
      "y": 0,
      "z": 6,
      "name": "Empty"
    },
    {
      "x": -2,
      "y": 1,
      "z": 6,
      "name": "Empty"
    },
    {
      "x": -2,
      "y": 2,
      "z": 6,
      "name": "Rock_Stone_Brick_Half",
      "rotation": 8
    },
    {
      "x": -2,
      "y": 3,
      "z": 6,
      "name": "Wood_Hardwood_Planks"
    },
    {
      "x": -2,
      "y": 4,
      "z": 6,
      "name": "Empty"
    },
    {
      "x": -2,
      "y": 5,
      "z": 6,
      "name": "Empty"
    },
    {
      "x": -2,
      "y": 6,
      "z": 6,
      "name": "Empty"
    },
    {
      "x": -2,
      "y": 7,
      "z": 6,
      "name": "Empty"
    },
    {
      "x": -2,
      "y": 8,
      "z": 6,
      "name": "Wood_Hardwood_Stairs",
      "rotation": 11
    },
    {
      "x": -2,
      "y": 9,
      "z": 6,
      "name": "HyDomum_Shingle__Soil_Clay_Smooth_Orange__Wood_Hardwood_Planks",
      "rotation": 3
    },
    {
      "x": -2,
      "y": 10,
      "z": 6,
      "name": "Empty"
    },
    {
      "x": -2,
      "y": 11,
      "z": 6,
      "name": "Empty"
    },
    {
      "x": -2,
      "y": 12,
      "z": 6,
      "name": "Empty"
    },
    {
      "x": -2,
      "y": 13,
      "z": 6,
      "name": "Empty"
    },
    {
      "x": -2,
      "y": -6,
      "z": 7,
      "name": "Rock_Stone_Cobble"
    },
    {
      "x": -2,
      "y": -5,
      "z": 7,
      "name": "Rock_Stone_Cobble"
    },
    {
      "x": -2,
      "y": -4,
      "z": 7,
      "name": "Rock_Stone_Cobble"
    },
    {
      "x": -2,
      "y": -3,
      "z": 7,
      "name": "Rock_Stone_Cobble"
    },
    {
      "x": -2,
      "y": -2,
      "z": 7,
      "name": "Soil_Dirt"
    },
    {
      "x": -2,
      "y": -1,
      "z": 7,
      "name": "Soil_Gravel"
    },
    {
      "x": -2,
      "y": 0,
      "z": 7,
      "name": "Empty"
    },
    {
      "x": -2,
      "y": 1,
      "z": 7,
      "name": "Empty"
    },
    {
      "x": -2,
      "y": 2,
      "z": 7,
      "name": "Empty"
    },
    {
      "x": -2,
      "y": 3,
      "z": 7,
      "name": "Wood_Hardwood_Planks"
    },
    {
      "x": -2,
      "y": 4,
      "z": 7,
      "name": "Empty"
    },
    {
      "x": -2,
      "y": 5,
      "z": 7,
      "name": "Empty"
    },
    {
      "x": -2,
      "y": 6,
      "z": 7,
      "name": "Empty"
    },
    {
      "x": -2,
      "y": 7,
      "z": 7,
      "name": "Empty"
    },
    {
      "x": -2,
      "y": 8,
      "z": 7,
      "name": "Wood_Hardwood_Stairs",
      "rotation": 11
    },
    {
      "x": -2,
      "y": 9,
      "z": 7,
      "name": "HyDomum_Shingle__Soil_Clay_Brick__Wood_Hardwood_Planks",
      "rotation": 3
    },
    {
      "x": -2,
      "y": 10,
      "z": 7,
      "name": "Empty"
    },
    {
      "x": -2,
      "y": 11,
      "z": 7,
      "name": "Empty"
    },
    {
      "x": -2,
      "y": 12,
      "z": 7,
      "name": "Empty"
    },
    {
      "x": -2,
      "y": 13,
      "z": 7,
      "name": "Empty"
    },
    {
      "x": -2,
      "y": -6,
      "z": 8,
      "name": "Rock_Stone_Cobble"
    },
    {
      "x": -2,
      "y": -5,
      "z": 8,
      "name": "Rock_Stone_Cobble"
    },
    {
      "x": -2,
      "y": -4,
      "z": 8,
      "name": "Rock_Stone_Cobble"
    },
    {
      "x": -2,
      "y": -3,
      "z": 8,
      "name": "Rock_Stone_Cobble"
    },
    {
      "x": -2,
      "y": -2,
      "z": 8,
      "name": "Rock_Stone_Cobble"
    },
    {
      "x": -2,
      "y": -1,
      "z": 8,
      "name": "Rock_Stone_Cobble_Stairs"
    },
    {
      "x": -2,
      "y": 0,
      "z": 8,
      "name": "Empty"
    },
    {
      "x": -2,
      "y": 1,
      "z": 8,
      "name": "Empty"
    },
    {
      "x": -2,
      "y": 2,
      "z": 8,
      "name": "Rock_Stone_Brick_Stairs",
      "rotation": 11
    },
    {
      "x": -2,
      "y": 3,
      "z": 8,
      "name": "Wood_Hardwood_Planks"
    },
    {
      "x": -2,
      "y": 4,
      "z": 8,
      "name": "Empty"
    },
    {
      "x": -2,
      "y": 5,
      "z": 8,
      "name": "Empty"
    },
    {
      "x": -2,
      "y": 6,
      "z": 8,
      "name": "Empty"
    },
    {
      "x": -2,
      "y": 7,
      "z": 8,
      "name": "Empty"
    },
    {
      "x": -2,
      "y": 8,
      "z": 8,
      "name": "Wood_Hardwood_Stairs",
      "rotation": 11
    },
    {
      "x": -2,
      "y": 9,
      "z": 8,
      "name": "HyDomum_Shingle__Soil_Clay_Brick__Wood_Hardwood_Planks",
      "rotation": 3
    },
    {
      "x": -2,
      "y": 10,
      "z": 8,
      "name": "Empty"
    },
    {
      "x": -2,
      "y": 11,
      "z": 8,
      "name": "Empty"
    },
    {
      "x": -2,
      "y": 12,
      "z": 8,
      "name": "Empty"
    },
    {
      "x": -2,
      "y": 13,
      "z": 8,
      "name": "Empty"
    },
    {
      "x": -2,
      "y": 0,
      "z": 9,
      "name": "Empty"
    },
    {
      "x": -2,
      "y": 1,
      "z": 9,
      "name": "Empty"
    },
    {
      "x": -2,
      "y": 2,
      "z": 9,
      "name": "Empty"
    },
    {
      "x": -2,
      "y": 3,
      "z": 9,
      "name": "Wood_Oak_Trunk",
      "support": 15,
      "rotation": 4
    },
    {
      "x": -2,
      "y": 4,
      "z": 9,
      "name": "Wood_Oak_Trunk",
      "support": 15
    },
    {
      "x": -2,
      "y": 5,
      "z": 9,
      "name": "Wood_Oak_Trunk",
      "support": 15
    },
    {
      "x": -2,
      "y": 6,
      "z": 9,
      "name": "Wood_Oak_Trunk",
      "support": 15
    },
    {
      "x": -2,
      "y": 7,
      "z": 9,
      "name": "Wood_Oak_Trunk",
      "support": 15,
      "rotation": 5
    },
    {
      "x": -2,
      "y": 8,
      "z": 9,
      "name": "HyDomum_TimberFrame_Plain__Wood_Hardwood_Planks__Soil_Clay_Smooth_White"
    },
    {
      "x": -2,
      "y": 9,
      "z": 9,
      "name": "HyDomum_Shingle__Soil_Clay_Smooth_Orange__Wood_Hardwood_Planks",
      "rotation": 3
    },
    {
      "x": -2,
      "y": 10,
      "z": 9,
      "name": "Empty"
    },
    {
      "x": -2,
      "y": 11,
      "z": 9,
      "name": "Empty"
    },
    {
      "x": -2,
      "y": 12,
      "z": 9,
      "name": "Empty"
    },
    {
      "x": -2,
      "y": 13,
      "z": 9,
      "name": "Empty"
    },
    {
      "x": -2,
      "y": 0,
      "z": 10,
      "name": "Empty"
    },
    {
      "x": -2,
      "y": 1,
      "z": 10,
      "name": "Empty"
    },
    {
      "x": -2,
      "y": 2,
      "z": 10,
      "name": "Empty"
    },
    {
      "x": -2,
      "y": 3,
      "z": 10,
      "name": "Empty"
    },
    {
      "x": -2,
      "y": 4,
      "z": 10,
      "name": "Empty"
    },
    {
      "x": -2,
      "y": 5,
      "z": 10,
      "name": "Empty"
    },
    {
      "x": -2,
      "y": 6,
      "z": 10,
      "name": "Wood_Oak_Trunk",
      "support": 15,
      "rotation": 4
    },
    {
      "x": -2,
      "y": 7,
      "z": 10,
      "name": "HyDomum_TimberFrame_OneCrossedLr__Wood_Hardwood_Planks__Soil_Clay_Smooth_White"
    },
    {
      "x": -2,
      "y": 8,
      "z": 10,
      "name": "Wood_Oak_Trunk",
      "support": 15
    },
    {
      "x": -2,
      "y": 9,
      "z": 10,
      "name": "HyDomum_Shingle__Soil_Clay_Brick__Wood_Hardwood_Planks",
      "rotation": 3
    },
    {
      "x": -2,
      "y": 10,
      "z": 10,
      "name": "Empty"
    },
    {
      "x": -2,
      "y": 11,
      "z": 10,
      "name": "Empty"
    },
    {
      "x": -2,
      "y": 12,
      "z": 10,
      "name": "Empty"
    },
    {
      "x": -2,
      "y": 13,
      "z": 10,
      "name": "Empty"
    },
    {
      "x": -2,
      "y": 0,
      "z": 11,
      "name": "Empty"
    },
    {
      "x": -2,
      "y": 1,
      "z": 11,
      "name": "Empty"
    },
    {
      "x": -2,
      "y": 2,
      "z": 11,
      "name": "Empty"
    },
    {
      "x": -2,
      "y": 3,
      "z": 11,
      "name": "Empty"
    },
    {
      "x": -2,
      "y": 4,
      "z": 11,
      "name": "Empty"
    },
    {
      "x": -2,
      "y": 5,
      "z": 11,
      "name": "Empty"
    },
    {
      "x": -2,
      "y": 6,
      "z": 11,
      "name": "Empty"
    },
    {
      "x": -2,
      "y": 7,
      "z": 11,
      "name": "Empty"
    },
    {
      "x": -2,
      "y": 8,
      "z": 11,
      "name": "Empty"
    },
    {
      "x": -2,
      "y": 9,
      "z": 11,
      "name": "Empty"
    },
    {
      "x": -2,
      "y": 10,
      "z": 11,
      "name": "Empty"
    },
    {
      "x": -2,
      "y": 11,
      "z": 11,
      "name": "Empty"
    },
    {
      "x": -2,
      "y": 12,
      "z": 11,
      "name": "Empty"
    },
    {
      "x": -2,
      "y": 13,
      "z": 11,
      "name": "Empty"
    },
    {
      "x": -1,
      "y": 0,
      "z": -2,
      "name": "Empty"
    },
    {
      "x": -1,
      "y": 1,
      "z": -2,
      "name": "Empty"
    },
    {
      "x": -1,
      "y": 2,
      "z": -2,
      "name": "Empty"
    },
    {
      "x": -1,
      "y": 3,
      "z": -2,
      "name": "Wood_Oak_Trunk",
      "support": 15,
      "rotation": 4
    },
    {
      "x": -1,
      "y": 4,
      "z": -2,
      "name": "Wood_Oak_Trunk",
      "support": 15
    },
    {
      "x": -1,
      "y": 5,
      "z": -2,
      "name": "Wood_Oak_Trunk",
      "support": 15
    },
    {
      "x": -1,
      "y": 6,
      "z": -2,
      "name": "Wood_Oak_Trunk",
      "support": 15
    },
    {
      "x": -1,
      "y": 7,
      "z": -2,
      "name": "Wood_Oak_Trunk",
      "support": 15,
      "rotation": 5
    },
    {
      "x": -1,
      "y": 8,
      "z": -2,
      "name": "HyDomum_TimberFrame_Plain__Wood_Hardwood_Planks__Soil_Clay_Smooth_White"
    },
    {
      "x": -1,
      "y": 9,
      "z": -2,
      "name": "Wood_Oak_Trunk",
      "support": 15
    },
    {
      "x": -1,
      "y": 10,
      "z": -2,
      "name": "*HyDomum_ShingleSlab__Soil_Clay_Smooth_Orange__Wood_Hardwood_Planks_State_Definitions_One_Way",
      "rotation": 2
    },
    {
      "x": -1,
      "y": 11,
      "z": -2,
      "name": "Empty"
    },
    {
      "x": -1,
      "y": 12,
      "z": -2,
      "name": "Empty"
    },
    {
      "x": -1,
      "y": 13,
      "z": -2,
      "name": "Empty"
    },
    {
      "x": -1,
      "y": -6,
      "z": -1,
      "name": "Rock_Stone_Brick"
    },
    {
      "x": -1,
      "y": -5,
      "z": -1,
      "name": "Wood_Hardwood_Stairs",
      "rotation": 10
    },
    {
      "x": -1,
      "y": -4,
      "z": -1,
      "name": "Wood_Hardwood_Stairs",
      "rotation": 10
    },
    {
      "x": -1,
      "y": -3,
      "z": -1,
      "name": "Wood_Hardwood_Stairs",
      "rotation": 10
    },
    {
      "x": -1,
      "y": -2,
      "z": -1,
      "name": "Rock_Stone_Brick"
    },
    {
      "x": -1,
      "y": -1,
      "z": -1,
      "name": "Rock_Stone_Brick"
    },
    {
      "x": -1,
      "y": 0,
      "z": -1,
      "name": "Rock_Stone_Brick"
    },
    {
      "x": -1,
      "y": 1,
      "z": -1,
      "name": "Rock_Stone_Brick"
    },
    {
      "x": -1,
      "y": 2,
      "z": -1,
      "name": "Rock_Stone_Brick"
    },
    {
      "x": -1,
      "y": 3,
      "z": -1,
      "name": "Wood_Oak_Trunk",
      "support": 15,
      "rotation": 5
    },
    {
      "x": -1,
      "y": 4,
      "z": -1,
      "name": "Empty"
    },
    {
      "x": -1,
      "y": 5,
      "z": -1,
      "name": "Empty"
    },
    {
      "x": -1,
      "y": 6,
      "z": -1,
      "name": "Empty"
    },
    {
      "x": -1,
      "y": 7,
      "z": -1,
      "name": "Empty"
    },
    {
      "x": -1,
      "y": 8,
      "z": -1,
      "name": "Empty"
    },
    {
      "x": -1,
      "y": 9,
      "z": -1,
      "name": "Wood_Oak_Trunk",
      "support": 15,
      "rotation": 4
    },
    {
      "x": -1,
      "y": 10,
      "z": -1,
      "name": "*HyDomum_ShingleSlab__Soil_Clay_Brick__Wood_Hardwood_Planks_State_Definitions_Two_Way"
    },
    {
      "x": -1,
      "y": 11,
      "z": -1,
      "name": "Empty"
    },
    {
      "x": -1,
      "y": 12,
      "z": -1,
      "name": "Empty"
    },
    {
      "x": -1,
      "y": 13,
      "z": -1,
      "name": "Empty"
    },
    {
      "x": -1,
      "y": -6,
      "z": 0,
      "name": "Rock_Stone_Brick"
    },
    {
      "x": -1,
      "y": -5,
      "z": 0,
      "name": "Furniture_Crude_Chest_Small",
      "rotation": 2,
      "components": {
        "Components": {
          "ItemContainerBlock": {
            "Capacity": 18
          }
        }
      }
    },
    {
      "x": -1,
      "y": -4,
      "z": 0,
      "name": "Empty"
    },
    {
      "x": -1,
      "y": -3,
      "z": 0,
      "name": "Empty"
    },
    {
      "x": -1,
      "y": -2,
      "z": 0,
      "name": "Rock_Stone_Cobble_Half",
      "rotation": 8
    },
    {
      "x": -1,
      "y": -1,
      "z": 0,
      "name": "Rock_Stone_Brick"
    },
    {
      "x": -1,
      "y": 0,
      "z": 0,
      "name": "Empty"
    },
    {
      "x": -1,
      "y": 1,
      "z": 0,
      "name": "Wood_Torch_Wall"
    },
    {
      "x": -1,
      "y": 2,
      "z": 0,
      "name": "Empty"
    },
    {
      "x": -1,
      "y": 3,
      "z": 0,
      "name": "Wood_Oak_Trunk",
      "support": 15,
      "rotation": 4
    },
    {
      "x": -1,
      "y": 4,
      "z": 0,
      "name": "Empty"
    },
    {
      "x": -1,
      "y": 5,
      "z": 0,
      "name": "Empty"
    },
    {
      "x": -1,
      "y": 6,
      "z": 0,
      "name": "Empty"
    },
    {
      "x": -1,
      "y": 7,
      "z": 0,
      "name": "Empty"
    },
    {
      "x": -1,
      "y": 8,
      "z": 0,
      "name": "Empty"
    },
    {
      "x": -1,
      "y": 9,
      "z": 0,
      "name": "Wood_Oak_Trunk",
      "support": 15,
      "rotation": 4
    },
    {
      "x": -1,
      "y": 10,
      "z": 0,
      "name": "*HyDomum_ShingleSlab__Soil_Clay_Brick__Wood_Hardwood_Planks_State_Definitions_Two_Way"
    },
    {
      "x": -1,
      "y": 11,
      "z": 0,
      "name": "Empty"
    },
    {
      "x": -1,
      "y": 12,
      "z": 0,
      "name": "Empty"
    },
    {
      "x": -1,
      "y": 13,
      "z": 0,
      "name": "Empty"
    },
    {
      "x": -1,
      "y": -6,
      "z": 1,
      "name": "Rock_Stone_Cobble"
    },
    {
      "x": -1,
      "y": -5,
      "z": 1,
      "name": "Wood_Birch_Trunk",
      "support": 15,
      "rotation": 5
    },
    {
      "x": -1,
      "y": -4,
      "z": 1,
      "name": "Empty"
    },
    {
      "x": -1,
      "y": -3,
      "z": 1,
      "name": "Empty"
    },
    {
      "x": -1,
      "y": -2,
      "z": 1,
      "name": "Rock_Stone_Cobble_Half",
      "rotation": 8
    },
    {
      "x": -1,
      "y": -1,
      "z": 1,
      "name": "Rock_Stone_Brick"
    },
    {
      "x": -1,
      "y": 0,
      "z": 1,
      "name": "*Furniture_Village_Trapdoor_State_Definitions_OpenDoorOut",
      "rotation": 1
    },
    {
      "x": -1,
      "y": 1,
      "z": 1,
      "name": "Empty"
    },
    {
      "x": -1,
      "y": 2,
      "z": 1,
      "name": "Empty"
    },
    {
      "x": -1,
      "y": 3,
      "z": 1,
      "name": "Wood_Oak_Trunk",
      "support": 15,
      "rotation": 4
    },
    {
      "x": -1,
      "y": 4,
      "z": 1,
      "name": "Empty"
    },
    {
      "x": -1,
      "y": 5,
      "z": 1,
      "name": "Empty"
    },
    {
      "x": -1,
      "y": 6,
      "z": 1,
      "name": "Empty"
    },
    {
      "x": -1,
      "y": 7,
      "z": 1,
      "name": "Empty"
    },
    {
      "x": -1,
      "y": 8,
      "z": 1,
      "name": "Empty"
    },
    {
      "x": -1,
      "y": 9,
      "z": 1,
      "name": "Wood_Oak_Trunk",
      "support": 15,
      "rotation": 4
    },
    {
      "x": -1,
      "y": 10,
      "z": 1,
      "name": "*HyDomum_ShingleSlab__Soil_Clay_Smooth_Orange__Wood_Hardwood_Planks_State_Definitions_Two_Way"
    },
    {
      "x": -1,
      "y": 11,
      "z": 1,
      "name": "Empty"
    },
    {
      "x": -1,
      "y": 12,
      "z": 1,
      "name": "Empty"
    },
    {
      "x": -1,
      "y": 13,
      "z": 1,
      "name": "Empty"
    },
    {
      "x": -1,
      "y": -6,
      "z": 2,
      "name": "Rock_Stone_Cobble"
    },
    {
      "x": -1,
      "y": -5,
      "z": 2,
      "name": "*HyDomum_Wall__Rock_Stone_Cobble_State_Definitions_End",
      "rotation": 1
    },
    {
      "x": -1,
      "y": -4,
      "z": 2,
      "name": "*HyDomum_Fence__Wood_Hardwood_Planks_State_Definitions_End",
      "rotation": 1
    },
    {
      "x": -1,
      "y": -3,
      "z": 2,
      "name": "*HyDomum_Fence__Wood_Hardwood_Planks_State_Definitions_End",
      "rotation": 1
    },
    {
      "x": -1,
      "y": -2,
      "z": 2,
      "name": "Rock_Stone_Brick"
    },
    {
      "x": -1,
      "y": -1,
      "z": 2,
      "name": "Rock_Stone_Brick"
    },
    {
      "x": -1,
      "y": 0,
      "z": 2,
      "name": "Empty"
    },
    {
      "x": -1,
      "y": 1,
      "z": 2,
      "name": "*Furniture_Village_Trapdoor_State_Definitions_OpenDoorOut",
      "rotation": 1
    },
    {
      "x": -1,
      "y": 2,
      "z": 2,
      "name": "Empty"
    },
    {
      "x": -1,
      "y": 3,
      "z": 2,
      "name": "Wood_Oak_Trunk",
      "support": 15,
      "rotation": 4
    },
    {
      "x": -1,
      "y": 4,
      "z": 2,
      "name": "Empty"
    },
    {
      "x": -1,
      "y": 5,
      "z": 2,
      "name": "Empty"
    },
    {
      "x": -1,
      "y": 6,
      "z": 2,
      "name": "Empty"
    },
    {
      "x": -1,
      "y": 7,
      "z": 2,
      "name": "Empty"
    },
    {
      "x": -1,
      "y": 8,
      "z": 2,
      "name": "Empty"
    },
    {
      "x": -1,
      "y": 9,
      "z": 2,
      "name": "Wood_Oak_Trunk",
      "support": 15,
      "rotation": 4
    },
    {
      "x": -1,
      "y": 10,
      "z": 2,
      "name": "*HyDomum_ShingleSlab__Soil_Clay_Brick__Wood_Hardwood_Planks_State_Definitions_Two_Way"
    },
    {
      "x": -1,
      "y": 11,
      "z": 2,
      "name": "Empty"
    },
    {
      "x": -1,
      "y": 12,
      "z": 2,
      "name": "Empty"
    },
    {
      "x": -1,
      "y": 13,
      "z": 2,
      "name": "Empty"
    },
    {
      "x": -1,
      "y": -6,
      "z": 3,
      "name": "Rock_Stone_Cobble"
    },
    {
      "x": -1,
      "y": -5,
      "z": 3,
      "name": "Rock_Stone_Cobble_Stairs",
      "rotation": 1
    },
    {
      "x": -1,
      "y": -4,
      "z": 3,
      "name": "Empty"
    },
    {
      "x": -1,
      "y": -3,
      "z": 3,
      "name": "Empty"
    },
    {
      "x": -1,
      "y": -2,
      "z": 3,
      "name": "Empty"
    },
    {
      "x": -1,
      "y": -1,
      "z": 3,
      "name": "Rock_Stone_Brick"
    },
    {
      "x": -1,
      "y": 0,
      "z": 3,
      "name": "HyVanilla_Carpet_Gray"
    },
    {
      "x": -1,
      "y": 1,
      "z": 3,
      "name": "Empty"
    },
    {
      "x": -1,
      "y": 2,
      "z": 3,
      "name": "*Furniture_Village_Trapdoor_State_Definitions_OpenDoorOut",
      "rotation": 1
    },
    {
      "x": -1,
      "y": 3,
      "z": 3,
      "name": "Wood_Oak_Trunk",
      "support": 15,
      "rotation": 4
    },
    {
      "x": -1,
      "y": 4,
      "z": 3,
      "name": "Empty"
    },
    {
      "x": -1,
      "y": 5,
      "z": 3,
      "name": "Empty"
    },
    {
      "x": -1,
      "y": 6,
      "z": 3,
      "name": "Empty"
    },
    {
      "x": -1,
      "y": 7,
      "z": 3,
      "name": "Empty"
    },
    {
      "x": -1,
      "y": 8,
      "z": 3,
      "name": "Empty"
    },
    {
      "x": -1,
      "y": 9,
      "z": 3,
      "name": "Wood_Oak_Trunk",
      "support": 15,
      "rotation": 4
    },
    {
      "x": -1,
      "y": 10,
      "z": 3,
      "name": "*HyDomum_ShingleSlab__Soil_Clay_Smooth_Orange__Wood_Hardwood_Planks_State_Definitions_Two_Way"
    },
    {
      "x": -1,
      "y": 11,
      "z": 3,
      "name": "Empty"
    },
    {
      "x": -1,
      "y": 12,
      "z": 3,
      "name": "Empty"
    },
    {
      "x": -1,
      "y": 13,
      "z": 3,
      "name": "Empty"
    },
    {
      "x": -1,
      "y": -6,
      "z": 4,
      "name": "Rock_Stone_Brick"
    },
    {
      "x": -1,
      "y": -5,
      "z": 4,
      "name": "Rock_Stone_Cobble"
    },
    {
      "x": -1,
      "y": -4,
      "z": 4,
      "name": "Rock_Stone_Cobble"
    },
    {
      "x": -1,
      "y": -3,
      "z": 4,
      "name": "Rock_Stone_Cobble"
    },
    {
      "x": -1,
      "y": -2,
      "z": 4,
      "name": "Rock_Stone_Brick"
    },
    {
      "x": -1,
      "y": -1,
      "z": 4,
      "name": "Rock_Stone_Brick"
    },
    {
      "x": -1,
      "y": 0,
      "z": 4,
      "name": "Rock_Stone_Brick"
    },
    {
      "x": -1,
      "y": 1,
      "z": 4,
      "name": "Rock_Stone_Brick"
    },
    {
      "x": -1,
      "y": 2,
      "z": 4,
      "name": "Rock_Stone_Brick"
    },
    {
      "x": -1,
      "y": 3,
      "z": 4,
      "name": "Wood_Oak_Trunk",
      "support": 15,
      "rotation": 4
    },
    {
      "x": -1,
      "y": 4,
      "z": 4,
      "name": "Empty"
    },
    {
      "x": -1,
      "y": 5,
      "z": 4,
      "name": "Wood_Torch_Wall",
      "rotation": 1
    },
    {
      "x": -1,
      "y": 6,
      "z": 4,
      "name": "Empty"
    },
    {
      "x": -1,
      "y": 7,
      "z": 4,
      "name": "Empty"
    },
    {
      "x": -1,
      "y": 8,
      "z": 4,
      "name": "Empty"
    },
    {
      "x": -1,
      "y": 9,
      "z": 4,
      "name": "Wood_Oak_Trunk",
      "support": 15,
      "rotation": 4
    },
    {
      "x": -1,
      "y": 10,
      "z": 4,
      "name": "*HyDomum_ShingleSlab__Soil_Clay_Brick__Wood_Hardwood_Planks_State_Definitions_Two_Way"
    },
    {
      "x": -1,
      "y": 11,
      "z": 4,
      "name": "Empty"
    },
    {
      "x": -1,
      "y": 12,
      "z": 4,
      "name": "Empty"
    },
    {
      "x": -1,
      "y": 13,
      "z": 4,
      "name": "Empty"
    },
    {
      "x": -1,
      "y": -6,
      "z": 5,
      "name": "Rock_Stone_Cobble"
    },
    {
      "x": -1,
      "y": -5,
      "z": 5,
      "name": "Rock_Stone_Cobble"
    },
    {
      "x": -1,
      "y": -4,
      "z": 5,
      "name": "Rock_Stone_Cobble"
    },
    {
      "x": -1,
      "y": -3,
      "z": 5,
      "name": "Rock_Stone_Cobble"
    },
    {
      "x": -1,
      "y": -2,
      "z": 5,
      "name": "Rock_Stone_Cobble"
    },
    {
      "x": -1,
      "y": -1,
      "z": 5,
      "name": "Rock_Stone_Cobble"
    },
    {
      "x": -1,
      "y": 0,
      "z": 5,
      "name": "Empty"
    },
    {
      "x": -1,
      "y": 1,
      "z": 5,
      "name": "Empty"
    },
    {
      "x": -1,
      "y": 2,
      "z": 5,
      "name": "Rock_Stone_Brick_Stairs",
      "rotation": 10
    },
    {
      "x": -1,
      "y": 3,
      "z": 5,
      "name": "Wood_Oak_Trunk",
      "support": 15,
      "rotation": 4
    },
    {
      "x": -1,
      "y": 4,
      "z": 5,
      "name": "Empty"
    },
    {
      "x": -1,
      "y": 5,
      "z": 5,
      "name": "Empty"
    },
    {
      "x": -1,
      "y": 6,
      "z": 5,
      "name": "Empty"
    },
    {
      "x": -1,
      "y": 7,
      "z": 5,
      "name": "Empty"
    },
    {
      "x": -1,
      "y": 8,
      "z": 5,
      "name": "Empty"
    },
    {
      "x": -1,
      "y": 9,
      "z": 5,
      "name": "Wood_Oak_Trunk",
      "support": 15,
      "rotation": 4
    },
    {
      "x": -1,
      "y": 10,
      "z": 5,
      "name": "*HyDomum_ShingleSlab__Soil_Clay_Brick__Wood_Hardwood_Planks_State_Definitions_Two_Way"
    },
    {
      "x": -1,
      "y": 11,
      "z": 5,
      "name": "Empty"
    },
    {
      "x": -1,
      "y": 12,
      "z": 5,
      "name": "Empty"
    },
    {
      "x": -1,
      "y": 13,
      "z": 5,
      "name": "Empty"
    },
    {
      "x": -1,
      "y": -6,
      "z": 6,
      "name": "Rock_Stone_Cobble"
    },
    {
      "x": -1,
      "y": -5,
      "z": 6,
      "name": "Rock_Stone_Cobble"
    },
    {
      "x": -1,
      "y": -4,
      "z": 6,
      "name": "Rock_Stone_Cobble"
    },
    {
      "x": -1,
      "y": -3,
      "z": 6,
      "name": "Rock_Stone_Cobble"
    },
    {
      "x": -1,
      "y": -2,
      "z": 6,
      "name": "Soil_Dirt"
    },
    {
      "x": -1,
      "y": -1,
      "z": 6,
      "name": "Soil_Gravel"
    },
    {
      "x": -1,
      "y": 0,
      "z": 6,
      "name": "Empty"
    },
    {
      "x": -1,
      "y": 1,
      "z": 6,
      "name": "Empty"
    },
    {
      "x": -1,
      "y": 2,
      "z": 6,
      "name": "Rock_Stone_Brick_Half",
      "rotation": 8
    },
    {
      "x": -1,
      "y": 3,
      "z": 6,
      "name": "Wood_Oak_Trunk",
      "support": 15,
      "rotation": 4
    },
    {
      "x": -1,
      "y": 4,
      "z": 6,
      "name": "Empty"
    },
    {
      "x": -1,
      "y": 5,
      "z": 6,
      "name": "Empty"
    },
    {
      "x": -1,
      "y": 6,
      "z": 6,
      "name": "Empty"
    },
    {
      "x": -1,
      "y": 7,
      "z": 6,
      "name": "Empty"
    },
    {
      "x": -1,
      "y": 8,
      "z": 6,
      "name": "Empty"
    },
    {
      "x": -1,
      "y": 9,
      "z": 6,
      "name": "Wood_Oak_Trunk",
      "support": 15,
      "rotation": 4
    },
    {
      "x": -1,
      "y": 10,
      "z": 6,
      "name": "*HyDomum_ShingleSlab__Soil_Clay_Brick__Wood_Hardwood_Planks_State_Definitions_Two_Way"
    },
    {
      "x": -1,
      "y": 11,
      "z": 6,
      "name": "Empty"
    },
    {
      "x": -1,
      "y": 12,
      "z": 6,
      "name": "Empty"
    },
    {
      "x": -1,
      "y": 13,
      "z": 6,
      "name": "Empty"
    },
    {
      "x": -1,
      "y": -6,
      "z": 7,
      "name": "Rock_Stone_Cobble"
    },
    {
      "x": -1,
      "y": -5,
      "z": 7,
      "name": "Rock_Stone_Cobble"
    },
    {
      "x": -1,
      "y": -4,
      "z": 7,
      "name": "Rock_Stone_Cobble"
    },
    {
      "x": -1,
      "y": -3,
      "z": 7,
      "name": "Rock_Stone_Cobble"
    },
    {
      "x": -1,
      "y": -2,
      "z": 7,
      "name": "Soil_Dirt"
    },
    {
      "x": -1,
      "y": -1,
      "z": 7,
      "name": "Soil_Gravel"
    },
    {
      "x": -1,
      "y": 0,
      "z": 7,
      "name": "Empty"
    },
    {
      "x": -1,
      "y": 1,
      "z": 7,
      "name": "Empty"
    },
    {
      "x": -1,
      "y": 2,
      "z": 7,
      "name": "Rock_Stone_Brick_Half",
      "rotation": 8
    },
    {
      "x": -1,
      "y": 3,
      "z": 7,
      "name": "Wood_Oak_Trunk",
      "support": 15,
      "rotation": 4
    },
    {
      "x": -1,
      "y": 4,
      "z": 7,
      "name": "Wood_Hardwood_Beam"
    },
    {
      "x": -1,
      "y": 5,
      "z": 7,
      "name": "Empty"
    },
    {
      "x": -1,
      "y": 6,
      "z": 7,
      "name": "Empty"
    },
    {
      "x": -1,
      "y": 7,
      "z": 7,
      "name": "Empty"
    },
    {
      "x": -1,
      "y": 8,
      "z": 7,
      "name": "Empty"
    },
    {
      "x": -1,
      "y": 9,
      "z": 7,
      "name": "Wood_Oak_Trunk",
      "support": 15,
      "rotation": 4
    },
    {
      "x": -1,
      "y": 10,
      "z": 7,
      "name": "*HyDomum_ShingleSlab__Soil_Clay_Smooth_Orange__Wood_Hardwood_Planks_State_Definitions_Two_Way"
    },
    {
      "x": -1,
      "y": 11,
      "z": 7,
      "name": "Empty"
    },
    {
      "x": -1,
      "y": 12,
      "z": 7,
      "name": "Empty"
    },
    {
      "x": -1,
      "y": 13,
      "z": 7,
      "name": "Empty"
    },
    {
      "x": -1,
      "y": -6,
      "z": 8,
      "name": "Rock_Stone_Cobble"
    },
    {
      "x": -1,
      "y": -5,
      "z": 8,
      "name": "Rock_Stone_Cobble"
    },
    {
      "x": -1,
      "y": -4,
      "z": 8,
      "name": "Rock_Stone_Cobble"
    },
    {
      "x": -1,
      "y": -3,
      "z": 8,
      "name": "Rock_Stone_Cobble"
    },
    {
      "x": -1,
      "y": -2,
      "z": 8,
      "name": "Rock_Stone_Cobble"
    },
    {
      "x": -1,
      "y": -1,
      "z": 8,
      "name": "Rock_Stone_Cobble_Stairs"
    },
    {
      "x": -1,
      "y": 0,
      "z": 8,
      "name": "Empty"
    },
    {
      "x": -1,
      "y": 1,
      "z": 8,
      "name": "Empty"
    },
    {
      "x": -1,
      "y": 2,
      "z": 8,
      "name": "Rock_Stone_Brick_Half",
      "rotation": 8
    },
    {
      "x": -1,
      "y": 3,
      "z": 8,
      "name": "Wood_Oak_Trunk",
      "support": 15,
      "rotation": 4
    },
    {
      "x": -1,
      "y": 4,
      "z": 8,
      "name": "Empty"
    },
    {
      "x": -1,
      "y": 5,
      "z": 8,
      "name": "Empty"
    },
    {
      "x": -1,
      "y": 6,
      "z": 8,
      "name": "Empty"
    },
    {
      "x": -1,
      "y": 7,
      "z": 8,
      "name": "Empty"
    },
    {
      "x": -1,
      "y": 8,
      "z": 8,
      "name": "Empty"
    },
    {
      "x": -1,
      "y": 9,
      "z": 8,
      "name": "Wood_Oak_Trunk",
      "support": 15,
      "rotation": 4
    },
    {
      "x": -1,
      "y": 10,
      "z": 8,
      "name": "*HyDomum_ShingleSlab__Soil_Clay_Smooth_Orange__Wood_Hardwood_Planks_State_Definitions_Two_Way"
    },
    {
      "x": -1,
      "y": 11,
      "z": 8,
      "name": "Empty"
    },
    {
      "x": -1,
      "y": 12,
      "z": 8,
      "name": "Empty"
    },
    {
      "x": -1,
      "y": 13,
      "z": 8,
      "name": "Empty"
    },
    {
      "x": -1,
      "y": 0,
      "z": 9,
      "name": "Empty"
    },
    {
      "x": -1,
      "y": 1,
      "z": 9,
      "name": "Empty"
    },
    {
      "x": -1,
      "y": 2,
      "z": 9,
      "name": "Empty"
    },
    {
      "x": -1,
      "y": 3,
      "z": 9,
      "name": "Wood_Oak_Trunk",
      "support": 15,
      "rotation": 5
    },
    {
      "x": -1,
      "y": 4,
      "z": 9,
      "name": "HyDomum_TimberFrame_Plain__Wood_Hardwood_Planks__Wood_Hardwood_Planks"
    },
    {
      "x": -1,
      "y": 5,
      "z": 9,
      "name": "Furniture_Village_Window"
    },
    {
      "x": -1,
      "y": 6,
      "z": 9,
      "name": "Wood_Oak_Trunk",
      "support": 15,
      "rotation": 5
    },
    {
      "x": -1,
      "y": 7,
      "z": 9,
      "name": "Wood_Oak_Trunk",
      "support": 15
    },
    {
      "x": -1,
      "y": 8,
      "z": 9,
      "name": "Wood_Oak_Trunk",
      "support": 15
    },
    {
      "x": -1,
      "y": 9,
      "z": 9,
      "name": "Wood_Oak_Trunk",
      "support": 15,
      "rotation": 4
    },
    {
      "x": -1,
      "y": 10,
      "z": 9,
      "name": "*HyDomum_ShingleSlab__Soil_Clay_Brick__Wood_Hardwood_Planks_State_Definitions_Two_Way"
    },
    {
      "x": -1,
      "y": 11,
      "z": 9,
      "name": "Empty"
    },
    {
      "x": -1,
      "y": 12,
      "z": 9,
      "name": "Empty"
    },
    {
      "x": -1,
      "y": 13,
      "z": 9,
      "name": "Empty"
    },
    {
      "x": -1,
      "y": 0,
      "z": 10,
      "name": "Empty"
    },
    {
      "x": -1,
      "y": 1,
      "z": 10,
      "name": "Empty"
    },
    {
      "x": -1,
      "y": 2,
      "z": 10,
      "name": "Empty"
    },
    {
      "x": -1,
      "y": 3,
      "z": 10,
      "name": "Empty"
    },
    {
      "x": -1,
      "y": 4,
      "z": 10,
      "name": "Empty"
    },
    {
      "x": -1,
      "y": 5,
      "z": 10,
      "name": "*Furniture_Village_Trapdoor_State_Definitions_OpenDoorOut",
      "rotation": 3
    },
    {
      "x": -1,
      "y": 6,
      "z": 10,
      "name": "Wood_Hardwood_Planks_Half",
      "rotation": 8
    },
    {
      "x": -1,
      "y": 7,
      "z": 10,
      "name": "HyDomum_TimberFrame_Plain__Wood_Hardwood_Planks__Soil_Clay_Smooth_White"
    },
    {
      "x": -1,
      "y": 8,
      "z": 10,
      "name": "HyDomum_TimberFrame_Plain__Wood_Hardwood_Planks__Soil_Clay_Smooth_White"
    },
    {
      "x": -1,
      "y": 9,
      "z": 10,
      "name": "Wood_Oak_Trunk",
      "support": 15
    },
    {
      "x": -1,
      "y": 10,
      "z": 10,
      "name": "*HyDomum_ShingleSlab__Soil_Clay_Brick__Wood_Hardwood_Planks_State_Definitions_One_Way"
    },
    {
      "x": -1,
      "y": 11,
      "z": 10,
      "name": "Empty"
    },
    {
      "x": -1,
      "y": 12,
      "z": 10,
      "name": "Empty"
    },
    {
      "x": -1,
      "y": 13,
      "z": 10,
      "name": "Empty"
    },
    {
      "x": -1,
      "y": 0,
      "z": 11,
      "name": "Empty"
    },
    {
      "x": -1,
      "y": 1,
      "z": 11,
      "name": "Empty"
    },
    {
      "x": -1,
      "y": 2,
      "z": 11,
      "name": "Empty"
    },
    {
      "x": -1,
      "y": 3,
      "z": 11,
      "name": "Empty"
    },
    {
      "x": -1,
      "y": 4,
      "z": 11,
      "name": "Empty"
    },
    {
      "x": -1,
      "y": 5,
      "z": 11,
      "name": "Empty"
    },
    {
      "x": -1,
      "y": 6,
      "z": 11,
      "name": "Empty"
    },
    {
      "x": -1,
      "y": 7,
      "z": 11,
      "name": "Empty"
    },
    {
      "x": -1,
      "y": 8,
      "z": 11,
      "name": "Empty"
    },
    {
      "x": -1,
      "y": 9,
      "z": 11,
      "name": "Empty"
    },
    {
      "x": -1,
      "y": 10,
      "z": 11,
      "name": "Empty"
    },
    {
      "x": -1,
      "y": 11,
      "z": 11,
      "name": "Empty"
    },
    {
      "x": -1,
      "y": 12,
      "z": 11,
      "name": "Empty"
    },
    {
      "x": -1,
      "y": 13,
      "z": 11,
      "name": "Empty"
    },
    {
      "x": 0,
      "y": 0,
      "z": -2,
      "name": "Empty"
    },
    {
      "x": 0,
      "y": 1,
      "z": -2,
      "name": "Empty"
    },
    {
      "x": 0,
      "y": 2,
      "z": -2,
      "name": "Empty"
    },
    {
      "x": 0,
      "y": 3,
      "z": -2,
      "name": "Wood_Oak_Trunk",
      "support": 15,
      "rotation": 5
    },
    {
      "x": 0,
      "y": 4,
      "z": -2,
      "name": "HyDomum_TimberFrame_Plain__Wood_Hardwood_Planks__Wood_Hardwood_Planks"
    },
    {
      "x": 0,
      "y": 5,
      "z": -2,
      "name": "HyDomum_TimberFrame_OneCrossedRl__Wood_Hardwood_Planks__Soil_Clay_Smooth_White"
    },
    {
      "x": 0,
      "y": 6,
      "z": -2,
      "name": "HyDomum_TimberFrame_OneCrossedRl__Wood_Hardwood_Planks__Soil_Clay_Smooth_White"
    },
    {
      "x": 0,
      "y": 7,
      "z": -2,
      "name": "Wood_Oak_Trunk",
      "support": 15,
      "rotation": 5
    },
    {
      "x": 0,
      "y": 8,
      "z": -2,
      "name": "Wood_Oak_Trunk",
      "support": 15
    },
    {
      "x": 0,
      "y": 9,
      "z": -2,
      "name": "HyDomum_Shingle__Soil_Clay_Brick__Wood_Hardwood_Planks",
      "rotation": 1
    },
    {
      "x": 0,
      "y": 10,
      "z": -2,
      "name": "Empty"
    },
    {
      "x": 0,
      "y": 11,
      "z": -2,
      "name": "Empty"
    },
    {
      "x": 0,
      "y": 12,
      "z": -2,
      "name": "Empty"
    },
    {
      "x": 0,
      "y": 13,
      "z": -2,
      "name": "Empty"
    },
    {
      "x": 0,
      "y": -6,
      "z": -1,
      "name": "Rock_Stone_Brick"
    },
    {
      "x": 0,
      "y": -5,
      "z": -1,
      "name": "Wood_Hardwood_Stairs",
      "rotation": 10
    },
    {
      "x": 0,
      "y": -4,
      "z": -1,
      "name": "Wood_Hardwood_Stairs",
      "rotation": 10
    },
    {
      "x": 0,
      "y": -3,
      "z": -1,
      "name": "Wood_Hardwood_Stairs",
      "rotation": 10
    },
    {
      "x": 0,
      "y": -2,
      "z": -1,
      "name": "Rock_Stone_Brick"
    },
    {
      "x": 0,
      "y": -1,
      "z": -1,
      "name": "Rock_Stone_Cobble"
    },
    {
      "x": 0,
      "y": 0,
      "z": -1,
      "name": "Rock_Stone_Cobble"
    },
    {
      "x": 0,
      "y": 1,
      "z": -1,
      "name": "Rock_Stone_Cobble"
    },
    {
      "x": 0,
      "y": 2,
      "z": -1,
      "name": "Rock_Stone_Cobble"
    },
    {
      "x": 0,
      "y": 3,
      "z": -1,
      "name": "Wood_Oak_Trunk",
      "support": 15,
      "rotation": 5
    },
    {
      "x": 0,
      "y": 4,
      "z": -1,
      "name": "*Furniture_Village_Trapdoor_State_Definitions_OpenDoorOut",
      "rotation": 3
    },
    {
      "x": 0,
      "y": 5,
      "z": -1,
      "name": "Empty"
    },
    {
      "x": 0,
      "y": 6,
      "z": -1,
      "name": "Empty"
    },
    {
      "x": 0,
      "y": 7,
      "z": -1,
      "name": "Empty"
    },
    {
      "x": 0,
      "y": 8,
      "z": -1,
      "name": "Wood_Hardwood_Stairs",
      "rotation": 9
    },
    {
      "x": 0,
      "y": 9,
      "z": -1,
      "name": "HyDomum_Shingle__Soil_Clay_Smooth_Orange__Wood_Hardwood_Planks",
      "rotation": 1
    },
    {
      "x": 0,
      "y": 10,
      "z": -1,
      "name": "Empty"
    },
    {
      "x": 0,
      "y": 11,
      "z": -1,
      "name": "Empty"
    },
    {
      "x": 0,
      "y": 12,
      "z": -1,
      "name": "Empty"
    },
    {
      "x": 0,
      "y": 13,
      "z": -1,
      "name": "Empty"
    },
    {
      "x": 0,
      "y": -6,
      "z": 0,
      "name": "Rock_Stone_Brick"
    },
    {
      "x": 0,
      "y": -5,
      "z": 0,
      "name": "Empty"
    },
    {
      "x": 0,
      "y": -4,
      "z": 0,
      "name": "Empty"
    },
    {
      "x": 0,
      "y": -3,
      "z": 0,
      "name": "Empty"
    },
    {
      "x": 0,
      "y": -2,
      "z": 0,
      "name": "Rock_Stone_Cobble_Half",
      "rotation": 8
    },
    {
      "x": 0,
      "y": -1,
      "z": 0,
      "name": "Rock_Stone_Brick"
    },
    {
      "x": 0,
      "y": 0,
      "z": 0,
      "name": "Editor_Anchor"
    },
